    2024-08-04 02:09:30,859 - ERROR - Exception on /api/get-all-tenders [GET]
Traceback (most recent call last):
  File "D:\practicum\kostiner-tenders\kostiner-tenders-back\controllers\tender_controller.py", line 33, in get
    list_array = tender_service.get_all(user, search_date)
                 ^^^^^^^^^^^^^^^^^^^^^^^^^^^^^^^^^^^^^^^^^
  File "D:\practicum\kostiner-tenders\kostiner-tenders-back\services\tender_service.py", line 31, in get_all
    abort(404, 'There are no tenders for this user')
  File "D:\practicum\kostiner-tenders\kostiner-tenders-back\.venv\Lib\site-packages\flask_restx\errors.py", line 28, in abort
    flask.abort(code)
  File "D:\practicum\kostiner-tenders\kostiner-tenders-back\.venv\Lib\site-packages\flask\helpers.py", line 272, in abort
    current_app.aborter(code, *args, **kwargs)
  File "D:\practicum\kostiner-tenders\kostiner-tenders-back\.venv\Lib\site-packages\werkzeug\exceptions.py", line 863, in __call__
    raise self.mapping[code](*args, **kwargs)
werkzeug.exceptions.NotFound: 404 Not Found: The requested URL was not found on the server. If you entered the URL manually please check your spelling and try again.

During handling of the above exception, another exception occurred:

Traceback (most recent call last):
  File "D:\practicum\kostiner-tenders\kostiner-tenders-back\.venv\Lib\site-packages\flask\app.py", line 880, in full_dispatch_request
    rv = self.dispatch_request()
         ^^^^^^^^^^^^^^^^^^^^^^^
  File "D:\practicum\kostiner-tenders\kostiner-tenders-back\.venv\Lib\site-packages\flask\app.py", line 865, in dispatch_request
    return self.ensure_sync(self.view_functions[rule.endpoint])(**view_args)  # type: ignore[no-any-return]
           ^^^^^^^^^^^^^^^^^^^^^^^^^^^^^^^^^^^^^^^^^^^^^^^^^^^^^^^^^^^^^^^^^
  File "D:\practicum\kostiner-tenders\kostiner-tenders-back\.venv\Lib\site-packages\flask_restx\api.py", line 402, in wrapper
    resp = resource(*args, **kwargs)
           ^^^^^^^^^^^^^^^^^^^^^^^^^
  File "D:\practicum\kostiner-tenders\kostiner-tenders-back\.venv\Lib\site-packages\flask\views.py", line 110, in view
    return current_app.ensure_sync(self.dispatch_request)(**kwargs)  # type: ignore[no-any-return]
           ^^^^^^^^^^^^^^^^^^^^^^^^^^^^^^^^^^^^^^^^^^^^^^^^^^^^^^^^
  File "D:\practicum\kostiner-tenders\kostiner-tenders-back\.venv\Lib\site-packages\flask_restx\resource.py", line 41, in dispatch_request
    resp = meth(*args, **kwargs)
           ^^^^^^^^^^^^^^^^^^^^^
  File "D:\practicum\kostiner-tenders\kostiner-tenders-back\.venv\Lib\site-packages\flask_restx\marshalling.py", line 244, in wrapper
    resp = f(*args, **kwargs)
           ^^^^^^^^^^^^^^^^^^
  File "D:\practicum\kostiner-tenders\kostiner-tenders-back\.venv\Lib\site-packages\flask_jwt_extended\view_decorators.py", line 170, in decorator
    return current_app.ensure_sync(fn)(*args, **kwargs)
           ^^^^^^^^^^^^^^^^^^^^^^^^^^^^^^^^^^^^^^^^^^^^
  File "D:\practicum\kostiner-tenders\kostiner-tenders-back\controllers\tender_controller.py", line 47, in get
    abort(500, "message: Internal server error. Please contact support.")
  File "D:\practicum\kostiner-tenders\kostiner-tenders-back\.venv\Lib\site-packages\flask_restx\errors.py", line 28, in abort
    flask.abort(code)
  File "D:\practicum\kostiner-tenders\kostiner-tenders-back\.venv\Lib\site-packages\flask\helpers.py", line 272, in abort
    current_app.aborter(code, *args, **kwargs)
  File "D:\practicum\kostiner-tenders\kostiner-tenders-back\.venv\Lib\site-packages\werkzeug\exceptions.py", line 863, in __call__
    raise self.mapping[code](*args, **kwargs)
werkzeug.exceptions.InternalServerError: 500 Internal Server Error: The server encountered an internal error and was unable to complete your request. Either the server is overloaded or there is an error in the application.
2024-08-04 10:07:05,315 - ERROR - Exception on /api/get-all-tenders [GET]
Traceback (most recent call last):
  File "D:\practicum\kostiner-tenders\kostiner-tenders-back\controllers\tender_controller.py", line 33, in get
    list_array = tender_service.get_all(user, search_date)
                 ^^^^^^^^^^^^^^^^^^^^^^^^^^^^^^^^^^^^^^^^^
  File "D:\practicum\kostiner-tenders\kostiner-tenders-back\services\tender_service.py", line 32, in get_all
    abort(404, 'There are no tenders for this user')
  File "D:\practicum\kostiner-tenders\kostiner-tenders-back\.venv\Lib\site-packages\flask_restx\errors.py", line 28, in abort
    flask.abort(code)
  File "D:\practicum\kostiner-tenders\kostiner-tenders-back\.venv\Lib\site-packages\flask\helpers.py", line 272, in abort
    current_app.aborter(code, *args, **kwargs)
  File "D:\practicum\kostiner-tenders\kostiner-tenders-back\.venv\Lib\site-packages\werkzeug\exceptions.py", line 863, in __call__
    raise self.mapping[code](*args, **kwargs)
werkzeug.exceptions.NotFound: 404 Not Found: The requested URL was not found on the server. If you entered the URL manually please check your spelling and try again.

During handling of the above exception, another exception occurred:

Traceback (most recent call last):
  File "D:\practicum\kostiner-tenders\kostiner-tenders-back\.venv\Lib\site-packages\flask\app.py", line 880, in full_dispatch_request
    rv = self.dispatch_request()
         ^^^^^^^^^^^^^^^^^^^^^^^
  File "D:\practicum\kostiner-tenders\kostiner-tenders-back\.venv\Lib\site-packages\flask\app.py", line 865, in dispatch_request
    return self.ensure_sync(self.view_functions[rule.endpoint])(**view_args)  # type: ignore[no-any-return]
           ^^^^^^^^^^^^^^^^^^^^^^^^^^^^^^^^^^^^^^^^^^^^^^^^^^^^^^^^^^^^^^^^^
  File "D:\practicum\kostiner-tenders\kostiner-tenders-back\.venv\Lib\site-packages\flask_restx\api.py", line 402, in wrapper
    resp = resource(*args, **kwargs)
           ^^^^^^^^^^^^^^^^^^^^^^^^^
  File "D:\practicum\kostiner-tenders\kostiner-tenders-back\.venv\Lib\site-packages\flask\views.py", line 110, in view
    return current_app.ensure_sync(self.dispatch_request)(**kwargs)  # type: ignore[no-any-return]
           ^^^^^^^^^^^^^^^^^^^^^^^^^^^^^^^^^^^^^^^^^^^^^^^^^^^^^^^^
  File "D:\practicum\kostiner-tenders\kostiner-tenders-back\.venv\Lib\site-packages\flask_restx\resource.py", line 41, in dispatch_request
    resp = meth(*args, **kwargs)
           ^^^^^^^^^^^^^^^^^^^^^
  File "D:\practicum\kostiner-tenders\kostiner-tenders-back\.venv\Lib\site-packages\flask_restx\marshalling.py", line 244, in wrapper
    resp = f(*args, **kwargs)
           ^^^^^^^^^^^^^^^^^^
  File "D:\practicum\kostiner-tenders\kostiner-tenders-back\.venv\Lib\site-packages\flask_jwt_extended\view_decorators.py", line 170, in decorator
    return current_app.ensure_sync(fn)(*args, **kwargs)
           ^^^^^^^^^^^^^^^^^^^^^^^^^^^^^^^^^^^^^^^^^^^^
  File "D:\practicum\kostiner-tenders\kostiner-tenders-back\controllers\tender_controller.py", line 47, in get
    abort(500, "message: Internal server error. Please contact support.")
  File "D:\practicum\kostiner-tenders\kostiner-tenders-back\.venv\Lib\site-packages\flask_restx\errors.py", line 28, in abort
    flask.abort(code)
  File "D:\practicum\kostiner-tenders\kostiner-tenders-back\.venv\Lib\site-packages\flask\helpers.py", line 272, in abort
    current_app.aborter(code, *args, **kwargs)
  File "D:\practicum\kostiner-tenders\kostiner-tenders-back\.venv\Lib\site-packages\werkzeug\exceptions.py", line 863, in __call__
    raise self.mapping[code](*args, **kwargs)
werkzeug.exceptions.InternalServerError: 500 Internal Server Error: The server encountered an internal error and was unable to complete your request. Either the server is overloaded or there is an error in the application.
2024-08-04 10:21:10,428 - werkzeug - WARNING -  * Debugger is active!
2024-08-04 10:21:10,435 - werkzeug - INFO -  * Debugger PIN: 120-157-398
2024-08-04 10:22:41,118 - werkzeug - INFO -  * Detected change in 'D:\\practicum\\kostiner-tenders\\kostiner-tenders-back\\controllers\\tender_controller.py', reloading
2024-08-04 10:22:57,555 - werkzeug - WARNING -  * Debugger is active!
2024-08-04 10:22:57,567 - werkzeug - INFO -  * Debugger PIN: 120-157-398
2024-08-04 10:23:51,364 - werkzeug - INFO -  * Detected change in 'D:\\practicum\\kostiner-tenders\\kostiner-tenders-back\\app\\app.py', reloading
2024-08-04 10:24:06,286 - werkzeug - WARNING -  * Debugger is active!
2024-08-04 10:24:06,295 - werkzeug - INFO -  * Debugger PIN: 120-157-398
2024-08-04 10:24:18,806 - werkzeug - INFO -  * Detected change in 'D:\\practicum\\kostiner-tenders\\kostiner-tenders-back\\app\\app.py', reloading
2024-08-04 10:24:32,360 - werkzeug - WARNING -  * Debugger is active!
2024-08-04 10:24:32,366 - werkzeug - INFO -  * Debugger PIN: 120-157-398
2024-08-04 10:25:24,585 - root - INFO - Request endpoint: tender_get_all_tenders
2024-08-04 10:25:24,652 - root - ERROR - msg err: There are no tenders for this user
2024-08-04 10:25:24,652 - root - ERROR - tender controller get No tenders found
2024-08-04 10:25:24,652 - root - ERROR - tender controller Exception msg: 404 Not Found: The requested URL was not found on the server. If you entered the URL manually please check your spelling and try again.
2024-08-04 10:25:24,652 - app - ERROR - Exception on /api/get-all-tenders [GET]
Traceback (most recent call last):
  File "D:\practicum\kostiner-tenders\kostiner-tenders-back\controllers\tender_controller.py", line 37, in get
    abort(404, "No tenders found.")
  File "D:\practicum\kostiner-tenders\kostiner-tenders-back\.venv\Lib\site-packages\flask_restx\errors.py", line 28, in abort
    flask.abort(code)
  File "D:\practicum\kostiner-tenders\kostiner-tenders-back\.venv\Lib\site-packages\flask\helpers.py", line 272, in abort
    current_app.aborter(code, *args, **kwargs)
  File "D:\practicum\kostiner-tenders\kostiner-tenders-back\.venv\Lib\site-packages\werkzeug\exceptions.py", line 863, in __call__
    raise self.mapping[code](*args, **kwargs)
werkzeug.exceptions.NotFound: 404 Not Found: The requested URL was not found on the server. If you entered the URL manually please check your spelling and try again.

During handling of the above exception, another exception occurred:

Traceback (most recent call last):
  File "D:\practicum\kostiner-tenders\kostiner-tenders-back\.venv\Lib\site-packages\flask\app.py", line 880, in full_dispatch_request
    rv = self.dispatch_request()
         ^^^^^^^^^^^^^^^^^^^^^^^
  File "D:\practicum\kostiner-tenders\kostiner-tenders-back\.venv\Lib\site-packages\flask\app.py", line 865, in dispatch_request
    return self.ensure_sync(self.view_functions[rule.endpoint])(**view_args)  # type: ignore[no-any-return]
           ^^^^^^^^^^^^^^^^^^^^^^^^^^^^^^^^^^^^^^^^^^^^^^^^^^^^^^^^^^^^^^^^^
  File "D:\practicum\kostiner-tenders\kostiner-tenders-back\.venv\Lib\site-packages\flask_restx\api.py", line 402, in wrapper
    resp = resource(*args, **kwargs)
           ^^^^^^^^^^^^^^^^^^^^^^^^^
  File "D:\practicum\kostiner-tenders\kostiner-tenders-back\.venv\Lib\site-packages\flask\views.py", line 110, in view
    return current_app.ensure_sync(self.dispatch_request)(**kwargs)  # type: ignore[no-any-return]
           ^^^^^^^^^^^^^^^^^^^^^^^^^^^^^^^^^^^^^^^^^^^^^^^^^^^^^^^^
  File "D:\practicum\kostiner-tenders\kostiner-tenders-back\.venv\Lib\site-packages\flask_restx\resource.py", line 41, in dispatch_request
    resp = meth(*args, **kwargs)
           ^^^^^^^^^^^^^^^^^^^^^
  File "D:\practicum\kostiner-tenders\kostiner-tenders-back\.venv\Lib\site-packages\flask_restx\marshalling.py", line 244, in wrapper
    resp = f(*args, **kwargs)
           ^^^^^^^^^^^^^^^^^^
  File "D:\practicum\kostiner-tenders\kostiner-tenders-back\.venv\Lib\site-packages\flask_jwt_extended\view_decorators.py", line 170, in decorator
    return current_app.ensure_sync(fn)(*args, **kwargs)
           ^^^^^^^^^^^^^^^^^^^^^^^^^^^^^^^^^^^^^^^^^^^^
  File "D:\practicum\kostiner-tenders\kostiner-tenders-back\controllers\tender_controller.py", line 49, in get
    abort(500, "message: Internal server error. Please contact support.")
  File "D:\practicum\kostiner-tenders\kostiner-tenders-back\.venv\Lib\site-packages\flask_restx\errors.py", line 28, in abort
    flask.abort(code)
  File "D:\practicum\kostiner-tenders\kostiner-tenders-back\.venv\Lib\site-packages\flask\helpers.py", line 272, in abort
    current_app.aborter(code, *args, **kwargs)
  File "D:\practicum\kostiner-tenders\kostiner-tenders-back\.venv\Lib\site-packages\werkzeug\exceptions.py", line 863, in __call__
    raise self.mapping[code](*args, **kwargs)
werkzeug.exceptions.InternalServerError: 500 Internal Server Error: The server encountered an internal error and was unable to complete your request. Either the server is overloaded or there is an error in the application.
2024-08-04 10:25:24,652 - app - ERROR - Exception on /api/get-all-tenders [GET]
Traceback (most recent call last):
  File "D:\practicum\kostiner-tenders\kostiner-tenders-back\controllers\tender_controller.py", line 37, in get
    abort(404, "No tenders found.")
  File "D:\practicum\kostiner-tenders\kostiner-tenders-back\.venv\Lib\site-packages\flask_restx\errors.py", line 28, in abort
    flask.abort(code)
  File "D:\practicum\kostiner-tenders\kostiner-tenders-back\.venv\Lib\site-packages\flask\helpers.py", line 272, in abort
    current_app.aborter(code, *args, **kwargs)
  File "D:\practicum\kostiner-tenders\kostiner-tenders-back\.venv\Lib\site-packages\werkzeug\exceptions.py", line 863, in __call__
    raise self.mapping[code](*args, **kwargs)
werkzeug.exceptions.NotFound: 404 Not Found: The requested URL was not found on the server. If you entered the URL manually please check your spelling and try again.

During handling of the above exception, another exception occurred:

Traceback (most recent call last):
  File "D:\practicum\kostiner-tenders\kostiner-tenders-back\.venv\Lib\site-packages\flask\app.py", line 880, in full_dispatch_request
    rv = self.dispatch_request()
         ^^^^^^^^^^^^^^^^^^^^^^^
  File "D:\practicum\kostiner-tenders\kostiner-tenders-back\.venv\Lib\site-packages\flask\app.py", line 865, in dispatch_request
    return self.ensure_sync(self.view_functions[rule.endpoint])(**view_args)  # type: ignore[no-any-return]
           ^^^^^^^^^^^^^^^^^^^^^^^^^^^^^^^^^^^^^^^^^^^^^^^^^^^^^^^^^^^^^^^^^
  File "D:\practicum\kostiner-tenders\kostiner-tenders-back\.venv\Lib\site-packages\flask_restx\api.py", line 402, in wrapper
    resp = resource(*args, **kwargs)
           ^^^^^^^^^^^^^^^^^^^^^^^^^
  File "D:\practicum\kostiner-tenders\kostiner-tenders-back\.venv\Lib\site-packages\flask\views.py", line 110, in view
    return current_app.ensure_sync(self.dispatch_request)(**kwargs)  # type: ignore[no-any-return]
           ^^^^^^^^^^^^^^^^^^^^^^^^^^^^^^^^^^^^^^^^^^^^^^^^^^^^^^^^
  File "D:\practicum\kostiner-tenders\kostiner-tenders-back\.venv\Lib\site-packages\flask_restx\resource.py", line 41, in dispatch_request
    resp = meth(*args, **kwargs)
           ^^^^^^^^^^^^^^^^^^^^^
  File "D:\practicum\kostiner-tenders\kostiner-tenders-back\.venv\Lib\site-packages\flask_restx\marshalling.py", line 244, in wrapper
    resp = f(*args, **kwargs)
           ^^^^^^^^^^^^^^^^^^
  File "D:\practicum\kostiner-tenders\kostiner-tenders-back\.venv\Lib\site-packages\flask_jwt_extended\view_decorators.py", line 170, in decorator
    return current_app.ensure_sync(fn)(*args, **kwargs)
           ^^^^^^^^^^^^^^^^^^^^^^^^^^^^^^^^^^^^^^^^^^^^
  File "D:\practicum\kostiner-tenders\kostiner-tenders-back\controllers\tender_controller.py", line 49, in get
    abort(500, "message: Internal server error. Please contact support.")
  File "D:\practicum\kostiner-tenders\kostiner-tenders-back\.venv\Lib\site-packages\flask_restx\errors.py", line 28, in abort
    flask.abort(code)
  File "D:\practicum\kostiner-tenders\kostiner-tenders-back\.venv\Lib\site-packages\flask\helpers.py", line 272, in abort
    current_app.aborter(code, *args, **kwargs)
  File "D:\practicum\kostiner-tenders\kostiner-tenders-back\.venv\Lib\site-packages\werkzeug\exceptions.py", line 863, in __call__
    raise self.mapping[code](*args, **kwargs)
werkzeug.exceptions.InternalServerError: 500 Internal Server Error: The server encountered an internal error and was unable to complete your request. Either the server is overloaded or there is an error in the application.
2024-08-04 10:25:24,685 - werkzeug - INFO - 127.0.0.1 - - [04/Aug/2024 10:25:24] "[35m[1mGET /api/get-all-tenders HTTP/1.1[0m" 500 -
2024-08-04 10:41:37,409 - werkzeug - INFO -  * Detected change in 'D:\\practicum\\kostiner-tenders\\kostiner-tenders-back\\app\\app.py', reloading
2024-08-04 10:42:13,280 - werkzeug - WARNING -  * Debugger is active!
2024-08-04 10:42:13,286 - werkzeug - INFO -  * Debugger PIN: 120-157-398
2024-08-04 10:42:13,439 - werkzeug - INFO - 127.0.0.1 - - [04/Aug/2024 10:42:13] "[31m[1mGET /api/get-all-tenders HTTP/1.1[0m" 401 -
2024-08-04 10:42:22,722 - werkzeug - INFO -  * Detected change in 'D:\\practicum\\kostiner-tenders\\kostiner-tenders-back\\app\\app.py', reloading
2024-08-04 10:42:41,095 - werkzeug - WARNING -  * Debugger is active!
2024-08-04 10:42:41,103 - werkzeug - INFO -  * Debugger PIN: 120-157-398
2024-08-04 10:42:41,413 - werkzeug - INFO - 127.0.0.1 - - [04/Aug/2024 10:42:41] "POST /auth/login HTTP/1.1" 200 -
2024-08-04 10:44:19,875 - root - INFO - Request endpoint: tender_get_all_tenders
2024-08-04 10:44:20,958 - root - ERROR - msg err: There are no tenders for this user
2024-08-04 10:44:20,958 - root - ERROR - tender controller get No tenders found
2024-08-04 10:44:20,958 - root - ERROR - tender controller Exception msg: 404 Not Found: The requested URL was not found on the server. If you entered the URL manually please check your spelling and try again.
2024-08-04 10:44:20,959 - app - ERROR - Exception on /api/get-all-tenders [GET]
Traceback (most recent call last):
  File "D:\practicum\kostiner-tenders\kostiner-tenders-back\controllers\tender_controller.py", line 37, in get
    abort(404, "No tenders found.")
  File "D:\practicum\kostiner-tenders\kostiner-tenders-back\.venv\Lib\site-packages\flask_restx\errors.py", line 28, in abort
    flask.abort(code)
  File "D:\practicum\kostiner-tenders\kostiner-tenders-back\.venv\Lib\site-packages\flask\helpers.py", line 272, in abort
    current_app.aborter(code, *args, **kwargs)
  File "D:\practicum\kostiner-tenders\kostiner-tenders-back\.venv\Lib\site-packages\werkzeug\exceptions.py", line 863, in __call__
    raise self.mapping[code](*args, **kwargs)
werkzeug.exceptions.NotFound: 404 Not Found: The requested URL was not found on the server. If you entered the URL manually please check your spelling and try again.

During handling of the above exception, another exception occurred:

Traceback (most recent call last):
  File "D:\practicum\kostiner-tenders\kostiner-tenders-back\.venv\Lib\site-packages\flask\app.py", line 880, in full_dispatch_request
    rv = self.dispatch_request()
         ^^^^^^^^^^^^^^^^^^^^^^^
  File "D:\practicum\kostiner-tenders\kostiner-tenders-back\.venv\Lib\site-packages\flask\app.py", line 865, in dispatch_request
    return self.ensure_sync(self.view_functions[rule.endpoint])(**view_args)  # type: ignore[no-any-return]
           ^^^^^^^^^^^^^^^^^^^^^^^^^^^^^^^^^^^^^^^^^^^^^^^^^^^^^^^^^^^^^^^^^
  File "D:\practicum\kostiner-tenders\kostiner-tenders-back\.venv\Lib\site-packages\flask_restx\api.py", line 402, in wrapper
    resp = resource(*args, **kwargs)
           ^^^^^^^^^^^^^^^^^^^^^^^^^
  File "D:\practicum\kostiner-tenders\kostiner-tenders-back\.venv\Lib\site-packages\flask\views.py", line 110, in view
    return current_app.ensure_sync(self.dispatch_request)(**kwargs)  # type: ignore[no-any-return]
           ^^^^^^^^^^^^^^^^^^^^^^^^^^^^^^^^^^^^^^^^^^^^^^^^^^^^^^^^
  File "D:\practicum\kostiner-tenders\kostiner-tenders-back\.venv\Lib\site-packages\flask_restx\resource.py", line 41, in dispatch_request
    resp = meth(*args, **kwargs)
           ^^^^^^^^^^^^^^^^^^^^^
  File "D:\practicum\kostiner-tenders\kostiner-tenders-back\.venv\Lib\site-packages\flask_restx\marshalling.py", line 244, in wrapper
    resp = f(*args, **kwargs)
           ^^^^^^^^^^^^^^^^^^
  File "D:\practicum\kostiner-tenders\kostiner-tenders-back\.venv\Lib\site-packages\flask_jwt_extended\view_decorators.py", line 170, in decorator
    return current_app.ensure_sync(fn)(*args, **kwargs)
           ^^^^^^^^^^^^^^^^^^^^^^^^^^^^^^^^^^^^^^^^^^^^
  File "D:\practicum\kostiner-tenders\kostiner-tenders-back\controllers\tender_controller.py", line 49, in get
    abort(500, "message: Internal server error. Please contact support.")
  File "D:\practicum\kostiner-tenders\kostiner-tenders-back\.venv\Lib\site-packages\flask_restx\errors.py", line 28, in abort
    flask.abort(code)
  File "D:\practicum\kostiner-tenders\kostiner-tenders-back\.venv\Lib\site-packages\flask\helpers.py", line 272, in abort
    current_app.aborter(code, *args, **kwargs)
  File "D:\practicum\kostiner-tenders\kostiner-tenders-back\.venv\Lib\site-packages\werkzeug\exceptions.py", line 863, in __call__
    raise self.mapping[code](*args, **kwargs)
werkzeug.exceptions.InternalServerError: 500 Internal Server Error: The server encountered an internal error and was unable to complete your request. Either the server is overloaded or there is an error in the application.
2024-08-04 10:44:20,993 - werkzeug - INFO - 127.0.0.1 - - [04/Aug/2024 10:44:20] "[35m[1mGET /api/get-all-tenders HTTP/1.1[0m" 500 -
2024-08-04 10:44:45,646 - werkzeug - INFO -  * Detected change in 'D:\\practicum\\kostiner-tenders\\kostiner-tenders-back\\app\\app.py', reloading
2024-08-04 10:49:59,797 - werkzeug - WARNING -  * Debugger is active!
2024-08-04 10:49:59,805 - werkzeug - INFO -  * Debugger PIN: 120-157-398
2024-08-04 10:49:59,922 - root - INFO - Request endpoint: tender_get_all_tenders
2024-08-04 10:50:00,578 - root - ERROR - msg err: There are no tenders for this user
2024-08-04 10:50:00,578 - root - ERROR - tender controller get No tenders found
2024-08-04 10:50:00,578 - root - ERROR - tender controller Exception msg: 404 Not Found: The requested URL was not found on the server. If you entered the URL manually please check your spelling and try again.
2024-08-04 10:50:00,578 - app - ERROR - Exception on /api/get-all-tenders [GET]
Traceback (most recent call last):
  File "D:\practicum\kostiner-tenders\kostiner-tenders-back\controllers\tender_controller.py", line 37, in get
    abort(404, "No tenders found.")
  File "D:\practicum\kostiner-tenders\kostiner-tenders-back\.venv\Lib\site-packages\flask_restx\errors.py", line 28, in abort
    flask.abort(code)
  File "D:\practicum\kostiner-tenders\kostiner-tenders-back\.venv\Lib\site-packages\flask\helpers.py", line 272, in abort
    current_app.aborter(code, *args, **kwargs)
  File "D:\practicum\kostiner-tenders\kostiner-tenders-back\.venv\Lib\site-packages\werkzeug\exceptions.py", line 863, in __call__
    raise self.mapping[code](*args, **kwargs)
werkzeug.exceptions.NotFound: 404 Not Found: The requested URL was not found on the server. If you entered the URL manually please check your spelling and try again.

During handling of the above exception, another exception occurred:

Traceback (most recent call last):
  File "D:\practicum\kostiner-tenders\kostiner-tenders-back\.venv\Lib\site-packages\flask\app.py", line 880, in full_dispatch_request
    rv = self.dispatch_request()
         ^^^^^^^^^^^^^^^^^^^^^^^
  File "D:\practicum\kostiner-tenders\kostiner-tenders-back\.venv\Lib\site-packages\flask\app.py", line 865, in dispatch_request
    return self.ensure_sync(self.view_functions[rule.endpoint])(**view_args)  # type: ignore[no-any-return]
           ^^^^^^^^^^^^^^^^^^^^^^^^^^^^^^^^^^^^^^^^^^^^^^^^^^^^^^^^^^^^^^^^^
  File "D:\practicum\kostiner-tenders\kostiner-tenders-back\.venv\Lib\site-packages\flask_restx\api.py", line 402, in wrapper
    resp = resource(*args, **kwargs)
           ^^^^^^^^^^^^^^^^^^^^^^^^^
  File "D:\practicum\kostiner-tenders\kostiner-tenders-back\.venv\Lib\site-packages\flask\views.py", line 110, in view
    return current_app.ensure_sync(self.dispatch_request)(**kwargs)  # type: ignore[no-any-return]
           ^^^^^^^^^^^^^^^^^^^^^^^^^^^^^^^^^^^^^^^^^^^^^^^^^^^^^^^^
  File "D:\practicum\kostiner-tenders\kostiner-tenders-back\.venv\Lib\site-packages\flask_restx\resource.py", line 41, in dispatch_request
    resp = meth(*args, **kwargs)
           ^^^^^^^^^^^^^^^^^^^^^
  File "D:\practicum\kostiner-tenders\kostiner-tenders-back\.venv\Lib\site-packages\flask_restx\marshalling.py", line 244, in wrapper
    resp = f(*args, **kwargs)
           ^^^^^^^^^^^^^^^^^^
  File "D:\practicum\kostiner-tenders\kostiner-tenders-back\.venv\Lib\site-packages\flask_jwt_extended\view_decorators.py", line 170, in decorator
    return current_app.ensure_sync(fn)(*args, **kwargs)
           ^^^^^^^^^^^^^^^^^^^^^^^^^^^^^^^^^^^^^^^^^^^^
  File "D:\practicum\kostiner-tenders\kostiner-tenders-back\controllers\tender_controller.py", line 49, in get
    abort(500, "message: Internal server error. Please contact support.")
  File "D:\practicum\kostiner-tenders\kostiner-tenders-back\.venv\Lib\site-packages\flask_restx\errors.py", line 28, in abort
    flask.abort(code)
  File "D:\practicum\kostiner-tenders\kostiner-tenders-back\.venv\Lib\site-packages\flask\helpers.py", line 272, in abort
    current_app.aborter(code, *args, **kwargs)
  File "D:\practicum\kostiner-tenders\kostiner-tenders-back\.venv\Lib\site-packages\werkzeug\exceptions.py", line 863, in __call__
    raise self.mapping[code](*args, **kwargs)
werkzeug.exceptions.InternalServerError: 500 Internal Server Error: The server encountered an internal error and was unable to complete your request. Either the server is overloaded or there is an error in the application.
2024-08-04 10:50:00,578 - app - ERROR - Exception on /api/get-all-tenders [GET]
Traceback (most recent call last):
  File "D:\practicum\kostiner-tenders\kostiner-tenders-back\controllers\tender_controller.py", line 37, in get
    abort(404, "No tenders found.")
  File "D:\practicum\kostiner-tenders\kostiner-tenders-back\.venv\Lib\site-packages\flask_restx\errors.py", line 28, in abort
    flask.abort(code)
  File "D:\practicum\kostiner-tenders\kostiner-tenders-back\.venv\Lib\site-packages\flask\helpers.py", line 272, in abort
    current_app.aborter(code, *args, **kwargs)
  File "D:\practicum\kostiner-tenders\kostiner-tenders-back\.venv\Lib\site-packages\werkzeug\exceptions.py", line 863, in __call__
    raise self.mapping[code](*args, **kwargs)
werkzeug.exceptions.NotFound: 404 Not Found: The requested URL was not found on the server. If you entered the URL manually please check your spelling and try again.

During handling of the above exception, another exception occurred:

Traceback (most recent call last):
  File "D:\practicum\kostiner-tenders\kostiner-tenders-back\.venv\Lib\site-packages\flask\app.py", line 880, in full_dispatch_request
    rv = self.dispatch_request()
         ^^^^^^^^^^^^^^^^^^^^^^^
  File "D:\practicum\kostiner-tenders\kostiner-tenders-back\.venv\Lib\site-packages\flask\app.py", line 865, in dispatch_request
    return self.ensure_sync(self.view_functions[rule.endpoint])(**view_args)  # type: ignore[no-any-return]
           ^^^^^^^^^^^^^^^^^^^^^^^^^^^^^^^^^^^^^^^^^^^^^^^^^^^^^^^^^^^^^^^^^
  File "D:\practicum\kostiner-tenders\kostiner-tenders-back\.venv\Lib\site-packages\flask_restx\api.py", line 402, in wrapper
    resp = resource(*args, **kwargs)
           ^^^^^^^^^^^^^^^^^^^^^^^^^
  File "D:\practicum\kostiner-tenders\kostiner-tenders-back\.venv\Lib\site-packages\flask\views.py", line 110, in view
    return current_app.ensure_sync(self.dispatch_request)(**kwargs)  # type: ignore[no-any-return]
           ^^^^^^^^^^^^^^^^^^^^^^^^^^^^^^^^^^^^^^^^^^^^^^^^^^^^^^^^
  File "D:\practicum\kostiner-tenders\kostiner-tenders-back\.venv\Lib\site-packages\flask_restx\resource.py", line 41, in dispatch_request
    resp = meth(*args, **kwargs)
           ^^^^^^^^^^^^^^^^^^^^^
  File "D:\practicum\kostiner-tenders\kostiner-tenders-back\.venv\Lib\site-packages\flask_restx\marshalling.py", line 244, in wrapper
    resp = f(*args, **kwargs)
           ^^^^^^^^^^^^^^^^^^
  File "D:\practicum\kostiner-tenders\kostiner-tenders-back\.venv\Lib\site-packages\flask_jwt_extended\view_decorators.py", line 170, in decorator
    return current_app.ensure_sync(fn)(*args, **kwargs)
           ^^^^^^^^^^^^^^^^^^^^^^^^^^^^^^^^^^^^^^^^^^^^
  File "D:\practicum\kostiner-tenders\kostiner-tenders-back\controllers\tender_controller.py", line 49, in get
    abort(500, "message: Internal server error. Please contact support.")
  File "D:\practicum\kostiner-tenders\kostiner-tenders-back\.venv\Lib\site-packages\flask_restx\errors.py", line 28, in abort
    flask.abort(code)
  File "D:\practicum\kostiner-tenders\kostiner-tenders-back\.venv\Lib\site-packages\flask\helpers.py", line 272, in abort
    current_app.aborter(code, *args, **kwargs)
  File "D:\practicum\kostiner-tenders\kostiner-tenders-back\.venv\Lib\site-packages\werkzeug\exceptions.py", line 863, in __call__
    raise self.mapping[code](*args, **kwargs)
werkzeug.exceptions.InternalServerError: 500 Internal Server Error: The server encountered an internal error and was unable to complete your request. Either the server is overloaded or there is an error in the application.
2024-08-04 10:50:00,592 - werkzeug - INFO - 127.0.0.1 - - [04/Aug/2024 10:50:00] "[35m[1mGET /api/get-all-tenders HTTP/1.1[0m" 500 -
2024-08-04 10:55:13,328 - root - INFO - Request endpoint: tender_get_all_tenders
2024-08-04 10:55:13,629 - root - ERROR - msg err: There are no tenders for this user
2024-08-04 10:55:13,629 - root - ERROR - tender controller get No tenders found
2024-08-04 10:55:13,630 - root - ERROR - tender controller Exception msg: 404 Not Found: The requested URL was not found on the server. If you entered the URL manually please check your spelling and try again.
2024-08-04 10:55:13,630 - app - ERROR - Exception on /api/get-all-tenders [GET]
Traceback (most recent call last):
  File "D:\practicum\kostiner-tenders\kostiner-tenders-back\controllers\tender_controller.py", line 37, in get
    abort(404, "No tenders found.")
  File "D:\practicum\kostiner-tenders\kostiner-tenders-back\.venv\Lib\site-packages\flask_restx\errors.py", line 28, in abort
    flask.abort(code)
  File "D:\practicum\kostiner-tenders\kostiner-tenders-back\.venv\Lib\site-packages\flask\helpers.py", line 272, in abort
    current_app.aborter(code, *args, **kwargs)
  File "D:\practicum\kostiner-tenders\kostiner-tenders-back\.venv\Lib\site-packages\werkzeug\exceptions.py", line 863, in __call__
    raise self.mapping[code](*args, **kwargs)
werkzeug.exceptions.NotFound: 404 Not Found: The requested URL was not found on the server. If you entered the URL manually please check your spelling and try again.

During handling of the above exception, another exception occurred:

Traceback (most recent call last):
  File "D:\practicum\kostiner-tenders\kostiner-tenders-back\.venv\Lib\site-packages\flask\app.py", line 880, in full_dispatch_request
    rv = self.dispatch_request()
         ^^^^^^^^^^^^^^^^^^^^^^^
  File "D:\practicum\kostiner-tenders\kostiner-tenders-back\.venv\Lib\site-packages\flask\app.py", line 865, in dispatch_request
    return self.ensure_sync(self.view_functions[rule.endpoint])(**view_args)  # type: ignore[no-any-return]
           ^^^^^^^^^^^^^^^^^^^^^^^^^^^^^^^^^^^^^^^^^^^^^^^^^^^^^^^^^^^^^^^^^
  File "D:\practicum\kostiner-tenders\kostiner-tenders-back\.venv\Lib\site-packages\flask_restx\api.py", line 402, in wrapper
    resp = resource(*args, **kwargs)
           ^^^^^^^^^^^^^^^^^^^^^^^^^
  File "D:\practicum\kostiner-tenders\kostiner-tenders-back\.venv\Lib\site-packages\flask\views.py", line 110, in view
    return current_app.ensure_sync(self.dispatch_request)(**kwargs)  # type: ignore[no-any-return]
           ^^^^^^^^^^^^^^^^^^^^^^^^^^^^^^^^^^^^^^^^^^^^^^^^^^^^^^^^
  File "D:\practicum\kostiner-tenders\kostiner-tenders-back\.venv\Lib\site-packages\flask_restx\resource.py", line 41, in dispatch_request
    resp = meth(*args, **kwargs)
           ^^^^^^^^^^^^^^^^^^^^^
  File "D:\practicum\kostiner-tenders\kostiner-tenders-back\.venv\Lib\site-packages\flask_restx\marshalling.py", line 244, in wrapper
    resp = f(*args, **kwargs)
           ^^^^^^^^^^^^^^^^^^
  File "D:\practicum\kostiner-tenders\kostiner-tenders-back\.venv\Lib\site-packages\flask_jwt_extended\view_decorators.py", line 170, in decorator
    return current_app.ensure_sync(fn)(*args, **kwargs)
           ^^^^^^^^^^^^^^^^^^^^^^^^^^^^^^^^^^^^^^^^^^^^
  File "D:\practicum\kostiner-tenders\kostiner-tenders-back\controllers\tender_controller.py", line 49, in get
    abort(500, "message: Internal server error. Please contact support.")
  File "D:\practicum\kostiner-tenders\kostiner-tenders-back\.venv\Lib\site-packages\flask_restx\errors.py", line 28, in abort
    flask.abort(code)
  File "D:\practicum\kostiner-tenders\kostiner-tenders-back\.venv\Lib\site-packages\flask\helpers.py", line 272, in abort
    current_app.aborter(code, *args, **kwargs)
  File "D:\practicum\kostiner-tenders\kostiner-tenders-back\.venv\Lib\site-packages\werkzeug\exceptions.py", line 863, in __call__
    raise self.mapping[code](*args, **kwargs)
werkzeug.exceptions.InternalServerError: 500 Internal Server Error: The server encountered an internal error and was unable to complete your request. Either the server is overloaded or there is an error in the application.
2024-08-04 10:55:13,630 - app - ERROR - Exception on /api/get-all-tenders [GET]
Traceback (most recent call last):
  File "D:\practicum\kostiner-tenders\kostiner-tenders-back\controllers\tender_controller.py", line 37, in get
    abort(404, "No tenders found.")
  File "D:\practicum\kostiner-tenders\kostiner-tenders-back\.venv\Lib\site-packages\flask_restx\errors.py", line 28, in abort
    flask.abort(code)
  File "D:\practicum\kostiner-tenders\kostiner-tenders-back\.venv\Lib\site-packages\flask\helpers.py", line 272, in abort
    current_app.aborter(code, *args, **kwargs)
  File "D:\practicum\kostiner-tenders\kostiner-tenders-back\.venv\Lib\site-packages\werkzeug\exceptions.py", line 863, in __call__
    raise self.mapping[code](*args, **kwargs)
werkzeug.exceptions.NotFound: 404 Not Found: The requested URL was not found on the server. If you entered the URL manually please check your spelling and try again.

During handling of the above exception, another exception occurred:

Traceback (most recent call last):
  File "D:\practicum\kostiner-tenders\kostiner-tenders-back\.venv\Lib\site-packages\flask\app.py", line 880, in full_dispatch_request
    rv = self.dispatch_request()
         ^^^^^^^^^^^^^^^^^^^^^^^
  File "D:\practicum\kostiner-tenders\kostiner-tenders-back\.venv\Lib\site-packages\flask\app.py", line 865, in dispatch_request
    return self.ensure_sync(self.view_functions[rule.endpoint])(**view_args)  # type: ignore[no-any-return]
           ^^^^^^^^^^^^^^^^^^^^^^^^^^^^^^^^^^^^^^^^^^^^^^^^^^^^^^^^^^^^^^^^^
  File "D:\practicum\kostiner-tenders\kostiner-tenders-back\.venv\Lib\site-packages\flask_restx\api.py", line 402, in wrapper
    resp = resource(*args, **kwargs)
           ^^^^^^^^^^^^^^^^^^^^^^^^^
  File "D:\practicum\kostiner-tenders\kostiner-tenders-back\.venv\Lib\site-packages\flask\views.py", line 110, in view
    return current_app.ensure_sync(self.dispatch_request)(**kwargs)  # type: ignore[no-any-return]
           ^^^^^^^^^^^^^^^^^^^^^^^^^^^^^^^^^^^^^^^^^^^^^^^^^^^^^^^^
  File "D:\practicum\kostiner-tenders\kostiner-tenders-back\.venv\Lib\site-packages\flask_restx\resource.py", line 41, in dispatch_request
    resp = meth(*args, **kwargs)
           ^^^^^^^^^^^^^^^^^^^^^
  File "D:\practicum\kostiner-tenders\kostiner-tenders-back\.venv\Lib\site-packages\flask_restx\marshalling.py", line 244, in wrapper
    resp = f(*args, **kwargs)
           ^^^^^^^^^^^^^^^^^^
  File "D:\practicum\kostiner-tenders\kostiner-tenders-back\.venv\Lib\site-packages\flask_jwt_extended\view_decorators.py", line 170, in decorator
    return current_app.ensure_sync(fn)(*args, **kwargs)
           ^^^^^^^^^^^^^^^^^^^^^^^^^^^^^^^^^^^^^^^^^^^^
  File "D:\practicum\kostiner-tenders\kostiner-tenders-back\controllers\tender_controller.py", line 49, in get
    abort(500, "message: Internal server error. Please contact support.")
  File "D:\practicum\kostiner-tenders\kostiner-tenders-back\.venv\Lib\site-packages\flask_restx\errors.py", line 28, in abort
    flask.abort(code)
  File "D:\practicum\kostiner-tenders\kostiner-tenders-back\.venv\Lib\site-packages\flask\helpers.py", line 272, in abort
    current_app.aborter(code, *args, **kwargs)
  File "D:\practicum\kostiner-tenders\kostiner-tenders-back\.venv\Lib\site-packages\werkzeug\exceptions.py", line 863, in __call__
    raise self.mapping[code](*args, **kwargs)
werkzeug.exceptions.InternalServerError: 500 Internal Server Error: The server encountered an internal error and was unable to complete your request. Either the server is overloaded or there is an error in the application.
2024-08-04 10:55:13,634 - werkzeug - INFO - 127.0.0.1 - - [04/Aug/2024 10:55:13] "[35m[1mGET /api/get-all-tenders HTTP/1.1[0m" 500 -
2024-08-04 10:55:30,702 - werkzeug - INFO - 127.0.0.1 - - [04/Aug/2024 10:55:30] "GET /api/get-all-users HTTP/1.1" 200 -
2024-08-04 10:56:41,983 - werkzeug - INFO - 127.0.0.1 - - [04/Aug/2024 10:56:41] "POST /auth/login HTTP/1.1" 200 -
2024-08-04 10:57:08,703 - root - INFO - Request endpoint: tender_get_all_tenders
2024-08-04 10:57:09,562 - root - ERROR - tender controller get No tenders found
2024-08-04 10:57:09,562 - root - ERROR - tender controller Exception msg: 404 Not Found: The requested URL was not found on the server. If you entered the URL manually please check your spelling and try again.
2024-08-04 10:57:09,562 - app - ERROR - Exception on /api/get-all-tenders [GET]
Traceback (most recent call last):
  File "D:\practicum\kostiner-tenders\kostiner-tenders-back\controllers\tender_controller.py", line 37, in get
    abort(404, "No tenders found.")
  File "D:\practicum\kostiner-tenders\kostiner-tenders-back\.venv\Lib\site-packages\flask_restx\errors.py", line 28, in abort
    flask.abort(code)
  File "D:\practicum\kostiner-tenders\kostiner-tenders-back\.venv\Lib\site-packages\flask\helpers.py", line 272, in abort
    current_app.aborter(code, *args, **kwargs)
  File "D:\practicum\kostiner-tenders\kostiner-tenders-back\.venv\Lib\site-packages\werkzeug\exceptions.py", line 863, in __call__
    raise self.mapping[code](*args, **kwargs)
werkzeug.exceptions.NotFound: 404 Not Found: The requested URL was not found on the server. If you entered the URL manually please check your spelling and try again.

During handling of the above exception, another exception occurred:

Traceback (most recent call last):
  File "D:\practicum\kostiner-tenders\kostiner-tenders-back\.venv\Lib\site-packages\flask\app.py", line 880, in full_dispatch_request
    rv = self.dispatch_request()
         ^^^^^^^^^^^^^^^^^^^^^^^
  File "D:\practicum\kostiner-tenders\kostiner-tenders-back\.venv\Lib\site-packages\flask\app.py", line 865, in dispatch_request
    return self.ensure_sync(self.view_functions[rule.endpoint])(**view_args)  # type: ignore[no-any-return]
           ^^^^^^^^^^^^^^^^^^^^^^^^^^^^^^^^^^^^^^^^^^^^^^^^^^^^^^^^^^^^^^^^^
  File "D:\practicum\kostiner-tenders\kostiner-tenders-back\.venv\Lib\site-packages\flask_restx\api.py", line 402, in wrapper
    resp = resource(*args, **kwargs)
           ^^^^^^^^^^^^^^^^^^^^^^^^^
  File "D:\practicum\kostiner-tenders\kostiner-tenders-back\.venv\Lib\site-packages\flask\views.py", line 110, in view
    return current_app.ensure_sync(self.dispatch_request)(**kwargs)  # type: ignore[no-any-return]
           ^^^^^^^^^^^^^^^^^^^^^^^^^^^^^^^^^^^^^^^^^^^^^^^^^^^^^^^^
  File "D:\practicum\kostiner-tenders\kostiner-tenders-back\.venv\Lib\site-packages\flask_restx\resource.py", line 41, in dispatch_request
    resp = meth(*args, **kwargs)
           ^^^^^^^^^^^^^^^^^^^^^
  File "D:\practicum\kostiner-tenders\kostiner-tenders-back\.venv\Lib\site-packages\flask_restx\marshalling.py", line 244, in wrapper
    resp = f(*args, **kwargs)
           ^^^^^^^^^^^^^^^^^^
  File "D:\practicum\kostiner-tenders\kostiner-tenders-back\.venv\Lib\site-packages\flask_jwt_extended\view_decorators.py", line 170, in decorator
    return current_app.ensure_sync(fn)(*args, **kwargs)
           ^^^^^^^^^^^^^^^^^^^^^^^^^^^^^^^^^^^^^^^^^^^^
  File "D:\practicum\kostiner-tenders\kostiner-tenders-back\controllers\tender_controller.py", line 49, in get
    abort(500, "message: Internal server error. Please contact support.")
  File "D:\practicum\kostiner-tenders\kostiner-tenders-back\.venv\Lib\site-packages\flask_restx\errors.py", line 28, in abort
    flask.abort(code)
  File "D:\practicum\kostiner-tenders\kostiner-tenders-back\.venv\Lib\site-packages\flask\helpers.py", line 272, in abort
    current_app.aborter(code, *args, **kwargs)
  File "D:\practicum\kostiner-tenders\kostiner-tenders-back\.venv\Lib\site-packages\werkzeug\exceptions.py", line 863, in __call__
    raise self.mapping[code](*args, **kwargs)
werkzeug.exceptions.InternalServerError: 500 Internal Server Error: The server encountered an internal error and was unable to complete your request. Either the server is overloaded or there is an error in the application.
2024-08-04 10:57:09,562 - app - ERROR - Exception on /api/get-all-tenders [GET]
Traceback (most recent call last):
  File "D:\practicum\kostiner-tenders\kostiner-tenders-back\controllers\tender_controller.py", line 37, in get
    abort(404, "No tenders found.")
  File "D:\practicum\kostiner-tenders\kostiner-tenders-back\.venv\Lib\site-packages\flask_restx\errors.py", line 28, in abort
    flask.abort(code)
  File "D:\practicum\kostiner-tenders\kostiner-tenders-back\.venv\Lib\site-packages\flask\helpers.py", line 272, in abort
    current_app.aborter(code, *args, **kwargs)
  File "D:\practicum\kostiner-tenders\kostiner-tenders-back\.venv\Lib\site-packages\werkzeug\exceptions.py", line 863, in __call__
    raise self.mapping[code](*args, **kwargs)
werkzeug.exceptions.NotFound: 404 Not Found: The requested URL was not found on the server. If you entered the URL manually please check your spelling and try again.

During handling of the above exception, another exception occurred:

Traceback (most recent call last):
  File "D:\practicum\kostiner-tenders\kostiner-tenders-back\.venv\Lib\site-packages\flask\app.py", line 880, in full_dispatch_request
    rv = self.dispatch_request()
         ^^^^^^^^^^^^^^^^^^^^^^^
  File "D:\practicum\kostiner-tenders\kostiner-tenders-back\.venv\Lib\site-packages\flask\app.py", line 865, in dispatch_request
    return self.ensure_sync(self.view_functions[rule.endpoint])(**view_args)  # type: ignore[no-any-return]
           ^^^^^^^^^^^^^^^^^^^^^^^^^^^^^^^^^^^^^^^^^^^^^^^^^^^^^^^^^^^^^^^^^
  File "D:\practicum\kostiner-tenders\kostiner-tenders-back\.venv\Lib\site-packages\flask_restx\api.py", line 402, in wrapper
    resp = resource(*args, **kwargs)
           ^^^^^^^^^^^^^^^^^^^^^^^^^
  File "D:\practicum\kostiner-tenders\kostiner-tenders-back\.venv\Lib\site-packages\flask\views.py", line 110, in view
    return current_app.ensure_sync(self.dispatch_request)(**kwargs)  # type: ignore[no-any-return]
           ^^^^^^^^^^^^^^^^^^^^^^^^^^^^^^^^^^^^^^^^^^^^^^^^^^^^^^^^
  File "D:\practicum\kostiner-tenders\kostiner-tenders-back\.venv\Lib\site-packages\flask_restx\resource.py", line 41, in dispatch_request
    resp = meth(*args, **kwargs)
           ^^^^^^^^^^^^^^^^^^^^^
  File "D:\practicum\kostiner-tenders\kostiner-tenders-back\.venv\Lib\site-packages\flask_restx\marshalling.py", line 244, in wrapper
    resp = f(*args, **kwargs)
           ^^^^^^^^^^^^^^^^^^
  File "D:\practicum\kostiner-tenders\kostiner-tenders-back\.venv\Lib\site-packages\flask_jwt_extended\view_decorators.py", line 170, in decorator
    return current_app.ensure_sync(fn)(*args, **kwargs)
           ^^^^^^^^^^^^^^^^^^^^^^^^^^^^^^^^^^^^^^^^^^^^
  File "D:\practicum\kostiner-tenders\kostiner-tenders-back\controllers\tender_controller.py", line 49, in get
    abort(500, "message: Internal server error. Please contact support.")
  File "D:\practicum\kostiner-tenders\kostiner-tenders-back\.venv\Lib\site-packages\flask_restx\errors.py", line 28, in abort
    flask.abort(code)
  File "D:\practicum\kostiner-tenders\kostiner-tenders-back\.venv\Lib\site-packages\flask\helpers.py", line 272, in abort
    current_app.aborter(code, *args, **kwargs)
  File "D:\practicum\kostiner-tenders\kostiner-tenders-back\.venv\Lib\site-packages\werkzeug\exceptions.py", line 863, in __call__
    raise self.mapping[code](*args, **kwargs)
werkzeug.exceptions.InternalServerError: 500 Internal Server Error: The server encountered an internal error and was unable to complete your request. Either the server is overloaded or there is an error in the application.
2024-08-04 10:57:09,562 - werkzeug - INFO - 127.0.0.1 - - [04/Aug/2024 10:57:09] "[35m[1mGET /api/get-all-tenders HTTP/1.1[0m" 500 -
2024-08-04 11:00:22,253 - werkzeug - INFO -  * Detected change in 'D:\\practicum\\kostiner-tenders\\kostiner-tenders-back\\services\\tender_service.py', reloading
2024-08-04 11:00:42,103 - werkzeug - WARNING -  * Debugger is active!
2024-08-04 11:00:42,109 - werkzeug - INFO -  * Debugger PIN: 120-157-398
2024-08-04 11:00:57,686 - root - INFO - Request endpoint: tender_get_all_tenders
2024-08-04 11:00:58,432 - root - ERROR - tender controller Exception msg: 500 Internal Server Error: The server encountered an internal error and was unable to complete your request. Either the server is overloaded or there is an error in the application.
2024-08-04 11:00:58,433 - app - ERROR - Exception on /api/get-all-tenders [GET]
Traceback (most recent call last):
  File "D:\practicum\kostiner-tenders\kostiner-tenders-back\controllers\tender_controller.py", line 34, in get
    list_array = tender_service.get_all(user, search_date)
                 ^^^^^^^^^^^^^^^^^^^^^^^^^^^^^^^^^^^^^^^^^
  File "D:\practicum\kostiner-tenders\kostiner-tenders-back\services\tender_service.py", line 31, in get_all
    abort(500, 'user invalid')
  File "D:\practicum\kostiner-tenders\kostiner-tenders-back\.venv\Lib\site-packages\flask_restx\errors.py", line 28, in abort
    flask.abort(code)
  File "D:\practicum\kostiner-tenders\kostiner-tenders-back\.venv\Lib\site-packages\flask\helpers.py", line 272, in abort
    current_app.aborter(code, *args, **kwargs)
  File "D:\practicum\kostiner-tenders\kostiner-tenders-back\.venv\Lib\site-packages\werkzeug\exceptions.py", line 863, in __call__
    raise self.mapping[code](*args, **kwargs)
werkzeug.exceptions.InternalServerError: 500 Internal Server Error: The server encountered an internal error and was unable to complete your request. Either the server is overloaded or there is an error in the application.

During handling of the above exception, another exception occurred:

Traceback (most recent call last):
  File "D:\practicum\kostiner-tenders\kostiner-tenders-back\.venv\Lib\site-packages\flask\app.py", line 880, in full_dispatch_request
    rv = self.dispatch_request()
         ^^^^^^^^^^^^^^^^^^^^^^^
  File "D:\practicum\kostiner-tenders\kostiner-tenders-back\.venv\Lib\site-packages\flask\app.py", line 865, in dispatch_request
    return self.ensure_sync(self.view_functions[rule.endpoint])(**view_args)  # type: ignore[no-any-return]
           ^^^^^^^^^^^^^^^^^^^^^^^^^^^^^^^^^^^^^^^^^^^^^^^^^^^^^^^^^^^^^^^^^
  File "D:\practicum\kostiner-tenders\kostiner-tenders-back\.venv\Lib\site-packages\flask_restx\api.py", line 402, in wrapper
    resp = resource(*args, **kwargs)
           ^^^^^^^^^^^^^^^^^^^^^^^^^
  File "D:\practicum\kostiner-tenders\kostiner-tenders-back\.venv\Lib\site-packages\flask\views.py", line 110, in view
    return current_app.ensure_sync(self.dispatch_request)(**kwargs)  # type: ignore[no-any-return]
           ^^^^^^^^^^^^^^^^^^^^^^^^^^^^^^^^^^^^^^^^^^^^^^^^^^^^^^^^
  File "D:\practicum\kostiner-tenders\kostiner-tenders-back\.venv\Lib\site-packages\flask_restx\resource.py", line 41, in dispatch_request
    resp = meth(*args, **kwargs)
           ^^^^^^^^^^^^^^^^^^^^^
  File "D:\practicum\kostiner-tenders\kostiner-tenders-back\.venv\Lib\site-packages\flask_restx\marshalling.py", line 244, in wrapper
    resp = f(*args, **kwargs)
           ^^^^^^^^^^^^^^^^^^
  File "D:\practicum\kostiner-tenders\kostiner-tenders-back\.venv\Lib\site-packages\flask_jwt_extended\view_decorators.py", line 170, in decorator
    return current_app.ensure_sync(fn)(*args, **kwargs)
           ^^^^^^^^^^^^^^^^^^^^^^^^^^^^^^^^^^^^^^^^^^^^
  File "D:\practicum\kostiner-tenders\kostiner-tenders-back\controllers\tender_controller.py", line 49, in get
    abort(500, "message: Internal server error. Please contact support.")
  File "D:\practicum\kostiner-tenders\kostiner-tenders-back\.venv\Lib\site-packages\flask_restx\errors.py", line 28, in abort
    flask.abort(code)
  File "D:\practicum\kostiner-tenders\kostiner-tenders-back\.venv\Lib\site-packages\flask\helpers.py", line 272, in abort
    current_app.aborter(code, *args, **kwargs)
  File "D:\practicum\kostiner-tenders\kostiner-tenders-back\.venv\Lib\site-packages\werkzeug\exceptions.py", line 863, in __call__
    raise self.mapping[code](*args, **kwargs)
werkzeug.exceptions.InternalServerError: 500 Internal Server Error: The server encountered an internal error and was unable to complete your request. Either the server is overloaded or there is an error in the application.
2024-08-04 11:00:58,433 - app - ERROR - Exception on /api/get-all-tenders [GET]
Traceback (most recent call last):
  File "D:\practicum\kostiner-tenders\kostiner-tenders-back\controllers\tender_controller.py", line 34, in get
    list_array = tender_service.get_all(user, search_date)
                 ^^^^^^^^^^^^^^^^^^^^^^^^^^^^^^^^^^^^^^^^^
  File "D:\practicum\kostiner-tenders\kostiner-tenders-back\services\tender_service.py", line 31, in get_all
    abort(500, 'user invalid')
  File "D:\practicum\kostiner-tenders\kostiner-tenders-back\.venv\Lib\site-packages\flask_restx\errors.py", line 28, in abort
    flask.abort(code)
  File "D:\practicum\kostiner-tenders\kostiner-tenders-back\.venv\Lib\site-packages\flask\helpers.py", line 272, in abort
    current_app.aborter(code, *args, **kwargs)
  File "D:\practicum\kostiner-tenders\kostiner-tenders-back\.venv\Lib\site-packages\werkzeug\exceptions.py", line 863, in __call__
    raise self.mapping[code](*args, **kwargs)
werkzeug.exceptions.InternalServerError: 500 Internal Server Error: The server encountered an internal error and was unable to complete your request. Either the server is overloaded or there is an error in the application.

During handling of the above exception, another exception occurred:

Traceback (most recent call last):
  File "D:\practicum\kostiner-tenders\kostiner-tenders-back\.venv\Lib\site-packages\flask\app.py", line 880, in full_dispatch_request
    rv = self.dispatch_request()
         ^^^^^^^^^^^^^^^^^^^^^^^
  File "D:\practicum\kostiner-tenders\kostiner-tenders-back\.venv\Lib\site-packages\flask\app.py", line 865, in dispatch_request
    return self.ensure_sync(self.view_functions[rule.endpoint])(**view_args)  # type: ignore[no-any-return]
           ^^^^^^^^^^^^^^^^^^^^^^^^^^^^^^^^^^^^^^^^^^^^^^^^^^^^^^^^^^^^^^^^^
  File "D:\practicum\kostiner-tenders\kostiner-tenders-back\.venv\Lib\site-packages\flask_restx\api.py", line 402, in wrapper
    resp = resource(*args, **kwargs)
           ^^^^^^^^^^^^^^^^^^^^^^^^^
  File "D:\practicum\kostiner-tenders\kostiner-tenders-back\.venv\Lib\site-packages\flask\views.py", line 110, in view
    return current_app.ensure_sync(self.dispatch_request)(**kwargs)  # type: ignore[no-any-return]
           ^^^^^^^^^^^^^^^^^^^^^^^^^^^^^^^^^^^^^^^^^^^^^^^^^^^^^^^^
  File "D:\practicum\kostiner-tenders\kostiner-tenders-back\.venv\Lib\site-packages\flask_restx\resource.py", line 41, in dispatch_request
    resp = meth(*args, **kwargs)
           ^^^^^^^^^^^^^^^^^^^^^
  File "D:\practicum\kostiner-tenders\kostiner-tenders-back\.venv\Lib\site-packages\flask_restx\marshalling.py", line 244, in wrapper
    resp = f(*args, **kwargs)
           ^^^^^^^^^^^^^^^^^^
  File "D:\practicum\kostiner-tenders\kostiner-tenders-back\.venv\Lib\site-packages\flask_jwt_extended\view_decorators.py", line 170, in decorator
    return current_app.ensure_sync(fn)(*args, **kwargs)
           ^^^^^^^^^^^^^^^^^^^^^^^^^^^^^^^^^^^^^^^^^^^^
  File "D:\practicum\kostiner-tenders\kostiner-tenders-back\controllers\tender_controller.py", line 49, in get
    abort(500, "message: Internal server error. Please contact support.")
  File "D:\practicum\kostiner-tenders\kostiner-tenders-back\.venv\Lib\site-packages\flask_restx\errors.py", line 28, in abort
    flask.abort(code)
  File "D:\practicum\kostiner-tenders\kostiner-tenders-back\.venv\Lib\site-packages\flask\helpers.py", line 272, in abort
    current_app.aborter(code, *args, **kwargs)
  File "D:\practicum\kostiner-tenders\kostiner-tenders-back\.venv\Lib\site-packages\werkzeug\exceptions.py", line 863, in __call__
    raise self.mapping[code](*args, **kwargs)
werkzeug.exceptions.InternalServerError: 500 Internal Server Error: The server encountered an internal error and was unable to complete your request. Either the server is overloaded or there is an error in the application.
2024-08-04 11:00:58,450 - werkzeug - INFO - 127.0.0.1 - - [04/Aug/2024 11:00:58] "[35m[1mGET /api/get-all-tenders HTTP/1.1[0m" 500 -
2024-08-04 11:03:16,531 - werkzeug - INFO -  * Detected change in 'D:\\practicum\\kostiner-tenders\\kostiner-tenders-back\\services\\tender_service.py', reloading
2024-08-04 11:03:42,553 - werkzeug - WARNING -  * Debugger is active!
2024-08-04 11:03:42,562 - werkzeug - INFO -  * Debugger PIN: 120-157-398
2024-08-04 11:03:46,120 - werkzeug - INFO -  * Detected change in 'D:\\practicum\\kostiner-tenders\\kostiner-tenders-back\\controllers\\tender_controller.py', reloading
2024-08-04 11:04:12,293 - werkzeug - WARNING -  * Debugger is active!
2024-08-04 11:04:12,300 - werkzeug - INFO -  * Debugger PIN: 120-157-398
2024-08-04 11:04:50,342 - app - ERROR - Exception on /api/get-all-tenders [GET]
Traceback (most recent call last):
  File "D:\practicum\kostiner-tenders\kostiner-tenders-back\controllers\tender_controller.py", line 34, in get
    list_array = tender_service.get_all(user, search_date)
                 ^^^^^^^^^^^^^^^^^^^^^^^^^^^^^^^^^^^^^^^^^
  File "D:\practicum\kostiner-tenders\kostiner-tenders-back\services\tender_service.py", line 31, in get_all
    abort(500, 'user invalid')
  File "D:\practicum\kostiner-tenders\kostiner-tenders-back\.venv\Lib\site-packages\flask_restx\errors.py", line 28, in abort
    flask.abort(code)
  File "D:\practicum\kostiner-tenders\kostiner-tenders-back\.venv\Lib\site-packages\flask\helpers.py", line 272, in abort
    current_app.aborter(code, *args, **kwargs)
  File "D:\practicum\kostiner-tenders\kostiner-tenders-back\.venv\Lib\site-packages\werkzeug\exceptions.py", line 863, in __call__
    raise self.mapping[code](*args, **kwargs)
werkzeug.exceptions.InternalServerError: 500 Internal Server Error: The server encountered an internal error and was unable to complete your request. Either the server is overloaded or there is an error in the application.

During handling of the above exception, another exception occurred:

Traceback (most recent call last):
  File "D:\practicum\kostiner-tenders\kostiner-tenders-back\.venv\Lib\site-packages\flask\app.py", line 880, in full_dispatch_request
    rv = self.dispatch_request()
         ^^^^^^^^^^^^^^^^^^^^^^^
  File "D:\practicum\kostiner-tenders\kostiner-tenders-back\.venv\Lib\site-packages\flask\app.py", line 865, in dispatch_request
    return self.ensure_sync(self.view_functions[rule.endpoint])(**view_args)  # type: ignore[no-any-return]
           ^^^^^^^^^^^^^^^^^^^^^^^^^^^^^^^^^^^^^^^^^^^^^^^^^^^^^^^^^^^^^^^^^
  File "D:\practicum\kostiner-tenders\kostiner-tenders-back\.venv\Lib\site-packages\flask_restx\api.py", line 402, in wrapper
    resp = resource(*args, **kwargs)
           ^^^^^^^^^^^^^^^^^^^^^^^^^
  File "D:\practicum\kostiner-tenders\kostiner-tenders-back\.venv\Lib\site-packages\flask\views.py", line 110, in view
    return current_app.ensure_sync(self.dispatch_request)(**kwargs)  # type: ignore[no-any-return]
           ^^^^^^^^^^^^^^^^^^^^^^^^^^^^^^^^^^^^^^^^^^^^^^^^^^^^^^^^
  File "D:\practicum\kostiner-tenders\kostiner-tenders-back\.venv\Lib\site-packages\flask_restx\resource.py", line 41, in dispatch_request
    resp = meth(*args, **kwargs)
           ^^^^^^^^^^^^^^^^^^^^^
  File "D:\practicum\kostiner-tenders\kostiner-tenders-back\.venv\Lib\site-packages\flask_restx\marshalling.py", line 244, in wrapper
    resp = f(*args, **kwargs)
           ^^^^^^^^^^^^^^^^^^
  File "D:\practicum\kostiner-tenders\kostiner-tenders-back\.venv\Lib\site-packages\flask_jwt_extended\view_decorators.py", line 170, in decorator
    return current_app.ensure_sync(fn)(*args, **kwargs)
           ^^^^^^^^^^^^^^^^^^^^^^^^^^^^^^^^^^^^^^^^^^^^
  File "D:\practicum\kostiner-tenders\kostiner-tenders-back\controllers\tender_controller.py", line 49, in get
    abort(500, "message: Internal server error. Please contact support.")
  File "D:\practicum\kostiner-tenders\kostiner-tenders-back\.venv\Lib\site-packages\flask_restx\errors.py", line 28, in abort
    flask.abort(code)
  File "D:\practicum\kostiner-tenders\kostiner-tenders-back\.venv\Lib\site-packages\flask\helpers.py", line 272, in abort
    current_app.aborter(code, *args, **kwargs)
  File "D:\practicum\kostiner-tenders\kostiner-tenders-back\.venv\Lib\site-packages\werkzeug\exceptions.py", line 863, in __call__
    raise self.mapping[code](*args, **kwargs)
werkzeug.exceptions.InternalServerError: 500 Internal Server Error: The server encountered an internal error and was unable to complete your request. Either the server is overloaded or there is an error in the application.
2024-08-04 11:04:50,342 - app - ERROR - Exception on /api/get-all-tenders [GET]
Traceback (most recent call last):
  File "D:\practicum\kostiner-tenders\kostiner-tenders-back\controllers\tender_controller.py", line 34, in get
    list_array = tender_service.get_all(user, search_date)
                 ^^^^^^^^^^^^^^^^^^^^^^^^^^^^^^^^^^^^^^^^^
  File "D:\practicum\kostiner-tenders\kostiner-tenders-back\services\tender_service.py", line 31, in get_all
    abort(500, 'user invalid')
  File "D:\practicum\kostiner-tenders\kostiner-tenders-back\.venv\Lib\site-packages\flask_restx\errors.py", line 28, in abort
    flask.abort(code)
  File "D:\practicum\kostiner-tenders\kostiner-tenders-back\.venv\Lib\site-packages\flask\helpers.py", line 272, in abort
    current_app.aborter(code, *args, **kwargs)
  File "D:\practicum\kostiner-tenders\kostiner-tenders-back\.venv\Lib\site-packages\werkzeug\exceptions.py", line 863, in __call__
    raise self.mapping[code](*args, **kwargs)
werkzeug.exceptions.InternalServerError: 500 Internal Server Error: The server encountered an internal error and was unable to complete your request. Either the server is overloaded or there is an error in the application.

During handling of the above exception, another exception occurred:

Traceback (most recent call last):
  File "D:\practicum\kostiner-tenders\kostiner-tenders-back\.venv\Lib\site-packages\flask\app.py", line 880, in full_dispatch_request
    rv = self.dispatch_request()
         ^^^^^^^^^^^^^^^^^^^^^^^
  File "D:\practicum\kostiner-tenders\kostiner-tenders-back\.venv\Lib\site-packages\flask\app.py", line 865, in dispatch_request
    return self.ensure_sync(self.view_functions[rule.endpoint])(**view_args)  # type: ignore[no-any-return]
           ^^^^^^^^^^^^^^^^^^^^^^^^^^^^^^^^^^^^^^^^^^^^^^^^^^^^^^^^^^^^^^^^^
  File "D:\practicum\kostiner-tenders\kostiner-tenders-back\.venv\Lib\site-packages\flask_restx\api.py", line 402, in wrapper
    resp = resource(*args, **kwargs)
           ^^^^^^^^^^^^^^^^^^^^^^^^^
  File "D:\practicum\kostiner-tenders\kostiner-tenders-back\.venv\Lib\site-packages\flask\views.py", line 110, in view
    return current_app.ensure_sync(self.dispatch_request)(**kwargs)  # type: ignore[no-any-return]
           ^^^^^^^^^^^^^^^^^^^^^^^^^^^^^^^^^^^^^^^^^^^^^^^^^^^^^^^^
  File "D:\practicum\kostiner-tenders\kostiner-tenders-back\.venv\Lib\site-packages\flask_restx\resource.py", line 41, in dispatch_request
    resp = meth(*args, **kwargs)
           ^^^^^^^^^^^^^^^^^^^^^
  File "D:\practicum\kostiner-tenders\kostiner-tenders-back\.venv\Lib\site-packages\flask_restx\marshalling.py", line 244, in wrapper
    resp = f(*args, **kwargs)
           ^^^^^^^^^^^^^^^^^^
  File "D:\practicum\kostiner-tenders\kostiner-tenders-back\.venv\Lib\site-packages\flask_jwt_extended\view_decorators.py", line 170, in decorator
    return current_app.ensure_sync(fn)(*args, **kwargs)
           ^^^^^^^^^^^^^^^^^^^^^^^^^^^^^^^^^^^^^^^^^^^^
  File "D:\practicum\kostiner-tenders\kostiner-tenders-back\controllers\tender_controller.py", line 49, in get
    abort(500, "message: Internal server error. Please contact support.")
  File "D:\practicum\kostiner-tenders\kostiner-tenders-back\.venv\Lib\site-packages\flask_restx\errors.py", line 28, in abort
    flask.abort(code)
  File "D:\practicum\kostiner-tenders\kostiner-tenders-back\.venv\Lib\site-packages\flask\helpers.py", line 272, in abort
    current_app.aborter(code, *args, **kwargs)
  File "D:\practicum\kostiner-tenders\kostiner-tenders-back\.venv\Lib\site-packages\werkzeug\exceptions.py", line 863, in __call__
    raise self.mapping[code](*args, **kwargs)
werkzeug.exceptions.InternalServerError: 500 Internal Server Error: The server encountered an internal error and was unable to complete your request. Either the server is overloaded or there is an error in the application.
2024-08-04 11:04:50,357 - werkzeug - INFO - 127.0.0.1 - - [04/Aug/2024 11:04:50] "[35m[1mGET /api/get-all-tenders HTTP/1.1[0m" 500 -
2024-08-04 11:12:39,967 - werkzeug - INFO -  * Detected change in 'D:\\practicum\\kostiner-tenders\\kostiner-tenders-back\\services\\user_service.py', reloading
2024-08-04 11:17:52,308 - werkzeug - INFO - [31m[1mWARNING: This is a development server. Do not use it in a production deployment. Use a production WSGI server instead.[0m
 * Running on http://127.0.0.1:5000
2024-08-04 11:17:52,308 - werkzeug - INFO - [33mPress CTRL+C to quit[0m
2024-08-04 11:17:52,308 - werkzeug - INFO -  * Restarting with stat
2024-08-04 11:18:26,056 - werkzeug - WARNING -  * Debugger is active!
2024-08-04 11:18:26,084 - werkzeug - INFO -  * Debugger PIN: 120-157-398
2024-08-04 11:18:49,806 - werkzeug - INFO - 127.0.0.1 - - [04/Aug/2024 11:18:49] "[31m[1mGET /api/get-all-tenders HTTP/1.1[0m" 401 -
2024-08-04 11:18:57,939 - werkzeug - INFO - 127.0.0.1 - - [04/Aug/2024 11:18:57] "POST /auth/login HTTP/1.1" 200 -
2024-08-04 11:19:19,291 - app - ERROR - Exception on /api/get-all-tenders [GET]
Traceback (most recent call last):
  File "D:\practicum\kostiner-tenders\kostiner-tenders-back\controllers\tender_controller.py", line 34, in get
    list_array = tender_service.get_all(user, search_date)
                 ^^^^^^^^^^^^^^^^^^^^^^^^^^^^^^^^^^^^^^^^^
  File "D:\practicum\kostiner-tenders\kostiner-tenders-back\services\tender_service.py", line 31, in get_all
    abort(500, 'user invalid')
  File "D:\practicum\kostiner-tenders\kostiner-tenders-back\.venv\Lib\site-packages\flask_restx\errors.py", line 28, in abort
    flask.abort(code)
  File "D:\practicum\kostiner-tenders\kostiner-tenders-back\.venv\Lib\site-packages\flask\helpers.py", line 272, in abort
    current_app.aborter(code, *args, **kwargs)
  File "D:\practicum\kostiner-tenders\kostiner-tenders-back\.venv\Lib\site-packages\werkzeug\exceptions.py", line 863, in __call__
    raise self.mapping[code](*args, **kwargs)
werkzeug.exceptions.InternalServerError: 500 Internal Server Error: The server encountered an internal error and was unable to complete your request. Either the server is overloaded or there is an error in the application.

During handling of the above exception, another exception occurred:

Traceback (most recent call last):
  File "D:\practicum\kostiner-tenders\kostiner-tenders-back\.venv\Lib\site-packages\flask\app.py", line 880, in full_dispatch_request
    rv = self.dispatch_request()
         ^^^^^^^^^^^^^^^^^^^^^^^
  File "D:\practicum\kostiner-tenders\kostiner-tenders-back\.venv\Lib\site-packages\flask\app.py", line 865, in dispatch_request
    return self.ensure_sync(self.view_functions[rule.endpoint])(**view_args)  # type: ignore[no-any-return]
           ^^^^^^^^^^^^^^^^^^^^^^^^^^^^^^^^^^^^^^^^^^^^^^^^^^^^^^^^^^^^^^^^^
  File "D:\practicum\kostiner-tenders\kostiner-tenders-back\.venv\Lib\site-packages\flask_restx\api.py", line 402, in wrapper
    resp = resource(*args, **kwargs)
           ^^^^^^^^^^^^^^^^^^^^^^^^^
  File "D:\practicum\kostiner-tenders\kostiner-tenders-back\.venv\Lib\site-packages\flask\views.py", line 110, in view
    return current_app.ensure_sync(self.dispatch_request)(**kwargs)  # type: ignore[no-any-return]
           ^^^^^^^^^^^^^^^^^^^^^^^^^^^^^^^^^^^^^^^^^^^^^^^^^^^^^^^^
  File "D:\practicum\kostiner-tenders\kostiner-tenders-back\.venv\Lib\site-packages\flask_restx\resource.py", line 41, in dispatch_request
    resp = meth(*args, **kwargs)
           ^^^^^^^^^^^^^^^^^^^^^
  File "D:\practicum\kostiner-tenders\kostiner-tenders-back\.venv\Lib\site-packages\flask_restx\marshalling.py", line 244, in wrapper
    resp = f(*args, **kwargs)
           ^^^^^^^^^^^^^^^^^^
  File "D:\practicum\kostiner-tenders\kostiner-tenders-back\.venv\Lib\site-packages\flask_jwt_extended\view_decorators.py", line 170, in decorator
    return current_app.ensure_sync(fn)(*args, **kwargs)
           ^^^^^^^^^^^^^^^^^^^^^^^^^^^^^^^^^^^^^^^^^^^^
  File "D:\practicum\kostiner-tenders\kostiner-tenders-back\controllers\tender_controller.py", line 49, in get
    abort(500, "message: Internal server error. Please contact support.")
  File "D:\practicum\kostiner-tenders\kostiner-tenders-back\.venv\Lib\site-packages\flask_restx\errors.py", line 28, in abort
    flask.abort(code)
  File "D:\practicum\kostiner-tenders\kostiner-tenders-back\.venv\Lib\site-packages\flask\helpers.py", line 272, in abort
    current_app.aborter(code, *args, **kwargs)
  File "D:\practicum\kostiner-tenders\kostiner-tenders-back\.venv\Lib\site-packages\werkzeug\exceptions.py", line 863, in __call__
    raise self.mapping[code](*args, **kwargs)
werkzeug.exceptions.InternalServerError: 500 Internal Server Error: The server encountered an internal error and was unable to complete your request. Either the server is overloaded or there is an error in the application.
2024-08-04 11:19:19,291 - app - ERROR - Exception on /api/get-all-tenders [GET]
Traceback (most recent call last):
  File "D:\practicum\kostiner-tenders\kostiner-tenders-back\controllers\tender_controller.py", line 34, in get
    list_array = tender_service.get_all(user, search_date)
                 ^^^^^^^^^^^^^^^^^^^^^^^^^^^^^^^^^^^^^^^^^
  File "D:\practicum\kostiner-tenders\kostiner-tenders-back\services\tender_service.py", line 31, in get_all
    abort(500, 'user invalid')
  File "D:\practicum\kostiner-tenders\kostiner-tenders-back\.venv\Lib\site-packages\flask_restx\errors.py", line 28, in abort
    flask.abort(code)
  File "D:\practicum\kostiner-tenders\kostiner-tenders-back\.venv\Lib\site-packages\flask\helpers.py", line 272, in abort
    current_app.aborter(code, *args, **kwargs)
  File "D:\practicum\kostiner-tenders\kostiner-tenders-back\.venv\Lib\site-packages\werkzeug\exceptions.py", line 863, in __call__
    raise self.mapping[code](*args, **kwargs)
werkzeug.exceptions.InternalServerError: 500 Internal Server Error: The server encountered an internal error and was unable to complete your request. Either the server is overloaded or there is an error in the application.

During handling of the above exception, another exception occurred:

Traceback (most recent call last):
  File "D:\practicum\kostiner-tenders\kostiner-tenders-back\.venv\Lib\site-packages\flask\app.py", line 880, in full_dispatch_request
    rv = self.dispatch_request()
         ^^^^^^^^^^^^^^^^^^^^^^^
  File "D:\practicum\kostiner-tenders\kostiner-tenders-back\.venv\Lib\site-packages\flask\app.py", line 865, in dispatch_request
    return self.ensure_sync(self.view_functions[rule.endpoint])(**view_args)  # type: ignore[no-any-return]
           ^^^^^^^^^^^^^^^^^^^^^^^^^^^^^^^^^^^^^^^^^^^^^^^^^^^^^^^^^^^^^^^^^
  File "D:\practicum\kostiner-tenders\kostiner-tenders-back\.venv\Lib\site-packages\flask_restx\api.py", line 402, in wrapper
    resp = resource(*args, **kwargs)
           ^^^^^^^^^^^^^^^^^^^^^^^^^
  File "D:\practicum\kostiner-tenders\kostiner-tenders-back\.venv\Lib\site-packages\flask\views.py", line 110, in view
    return current_app.ensure_sync(self.dispatch_request)(**kwargs)  # type: ignore[no-any-return]
           ^^^^^^^^^^^^^^^^^^^^^^^^^^^^^^^^^^^^^^^^^^^^^^^^^^^^^^^^
  File "D:\practicum\kostiner-tenders\kostiner-tenders-back\.venv\Lib\site-packages\flask_restx\resource.py", line 41, in dispatch_request
    resp = meth(*args, **kwargs)
           ^^^^^^^^^^^^^^^^^^^^^
  File "D:\practicum\kostiner-tenders\kostiner-tenders-back\.venv\Lib\site-packages\flask_restx\marshalling.py", line 244, in wrapper
    resp = f(*args, **kwargs)
           ^^^^^^^^^^^^^^^^^^
  File "D:\practicum\kostiner-tenders\kostiner-tenders-back\.venv\Lib\site-packages\flask_jwt_extended\view_decorators.py", line 170, in decorator
    return current_app.ensure_sync(fn)(*args, **kwargs)
           ^^^^^^^^^^^^^^^^^^^^^^^^^^^^^^^^^^^^^^^^^^^^
  File "D:\practicum\kostiner-tenders\kostiner-tenders-back\controllers\tender_controller.py", line 49, in get
    abort(500, "message: Internal server error. Please contact support.")
  File "D:\practicum\kostiner-tenders\kostiner-tenders-back\.venv\Lib\site-packages\flask_restx\errors.py", line 28, in abort
    flask.abort(code)
  File "D:\practicum\kostiner-tenders\kostiner-tenders-back\.venv\Lib\site-packages\flask\helpers.py", line 272, in abort
    current_app.aborter(code, *args, **kwargs)
  File "D:\practicum\kostiner-tenders\kostiner-tenders-back\.venv\Lib\site-packages\werkzeug\exceptions.py", line 863, in __call__
    raise self.mapping[code](*args, **kwargs)
werkzeug.exceptions.InternalServerError: 500 Internal Server Error: The server encountered an internal error and was unable to complete your request. Either the server is overloaded or there is an error in the application.
2024-08-04 11:19:19,305 - werkzeug - INFO - 127.0.0.1 - - [04/Aug/2024 11:19:19] "[35m[1mGET /api/get-all-tenders HTTP/1.1[0m" 500 -
2024-08-04 11:25:32,447 - werkzeug - INFO -  * Detected change in 'D:\\practicum\\kostiner-tenders\\kostiner-tenders-back\\services\\user_service.py', reloading
2024-08-04 11:25:33,092 - werkzeug - INFO -  * Restarting with stat
2024-08-04 11:26:17,559 - werkzeug - WARNING -  * Debugger is active!
2024-08-04 11:26:17,568 - werkzeug - INFO -  * Debugger PIN: 120-157-398
2024-08-04 11:28:36,572 - werkzeug - INFO -  * Detected change in 'D:\\practicum\\kostiner-tenders\\kostiner-tenders-back\\app\\app.py', reloading
2024-08-04 11:28:37,125 - werkzeug - INFO -  * Restarting with stat
2024-08-04 11:29:27,527 - werkzeug - WARNING -  * Debugger is active!
2024-08-04 11:29:27,535 - werkzeug - INFO -  * Debugger PIN: 120-157-398
2024-08-04 11:29:41,147 - root - ERROR - tender controller Exception msg: 500 Internal Server Error: The server encountered an internal error and was unable to complete your request. Either the server is overloaded or there is an error in the application.
2024-08-04 11:29:41,147 - app - ERROR - Exception on /api/get-all-tenders [GET]
Traceback (most recent call last):
  File "D:\practicum\kostiner-tenders\kostiner-tenders-back\controllers\tender_controller.py", line 33, in get
    list_array = tender_service.get_all(user, search_date)
                 ^^^^^^^^^^^^^^^^^^^^^^^^^^^^^^^^^^^^^^^^^
  File "D:\practicum\kostiner-tenders\kostiner-tenders-back\services\tender_service.py", line 31, in get_all
    abort(500, 'user invalid')
  File "D:\practicum\kostiner-tenders\kostiner-tenders-back\.venv\Lib\site-packages\flask_restx\errors.py", line 28, in abort
    flask.abort(code)
  File "D:\practicum\kostiner-tenders\kostiner-tenders-back\.venv\Lib\site-packages\flask\helpers.py", line 272, in abort
    current_app.aborter(code, *args, **kwargs)
  File "D:\practicum\kostiner-tenders\kostiner-tenders-back\.venv\Lib\site-packages\werkzeug\exceptions.py", line 863, in __call__
    raise self.mapping[code](*args, **kwargs)
werkzeug.exceptions.InternalServerError: 500 Internal Server Error: The server encountered an internal error and was unable to complete your request. Either the server is overloaded or there is an error in the application.

During handling of the above exception, another exception occurred:

Traceback (most recent call last):
  File "D:\practicum\kostiner-tenders\kostiner-tenders-back\.venv\Lib\site-packages\flask\app.py", line 880, in full_dispatch_request
    rv = self.dispatch_request()
         ^^^^^^^^^^^^^^^^^^^^^^^
  File "D:\practicum\kostiner-tenders\kostiner-tenders-back\.venv\Lib\site-packages\flask\app.py", line 865, in dispatch_request
    return self.ensure_sync(self.view_functions[rule.endpoint])(**view_args)  # type: ignore[no-any-return]
           ^^^^^^^^^^^^^^^^^^^^^^^^^^^^^^^^^^^^^^^^^^^^^^^^^^^^^^^^^^^^^^^^^
  File "D:\practicum\kostiner-tenders\kostiner-tenders-back\.venv\Lib\site-packages\flask_restx\api.py", line 402, in wrapper
    resp = resource(*args, **kwargs)
           ^^^^^^^^^^^^^^^^^^^^^^^^^
  File "D:\practicum\kostiner-tenders\kostiner-tenders-back\.venv\Lib\site-packages\flask\views.py", line 110, in view
    return current_app.ensure_sync(self.dispatch_request)(**kwargs)  # type: ignore[no-any-return]
           ^^^^^^^^^^^^^^^^^^^^^^^^^^^^^^^^^^^^^^^^^^^^^^^^^^^^^^^^
  File "D:\practicum\kostiner-tenders\kostiner-tenders-back\.venv\Lib\site-packages\flask_restx\resource.py", line 41, in dispatch_request
    resp = meth(*args, **kwargs)
           ^^^^^^^^^^^^^^^^^^^^^
  File "D:\practicum\kostiner-tenders\kostiner-tenders-back\.venv\Lib\site-packages\flask_restx\marshalling.py", line 244, in wrapper
    resp = f(*args, **kwargs)
           ^^^^^^^^^^^^^^^^^^
  File "D:\practicum\kostiner-tenders\kostiner-tenders-back\.venv\Lib\site-packages\flask_jwt_extended\view_decorators.py", line 170, in decorator
    return current_app.ensure_sync(fn)(*args, **kwargs)
           ^^^^^^^^^^^^^^^^^^^^^^^^^^^^^^^^^^^^^^^^^^^^
  File "D:\practicum\kostiner-tenders\kostiner-tenders-back\controllers\tender_controller.py", line 47, in get
    abort(500, "message: Internal server error. Please contact support.")
  File "D:\practicum\kostiner-tenders\kostiner-tenders-back\.venv\Lib\site-packages\flask_restx\errors.py", line 28, in abort
    flask.abort(code)
  File "D:\practicum\kostiner-tenders\kostiner-tenders-back\.venv\Lib\site-packages\flask\helpers.py", line 272, in abort
    current_app.aborter(code, *args, **kwargs)
  File "D:\practicum\kostiner-tenders\kostiner-tenders-back\.venv\Lib\site-packages\werkzeug\exceptions.py", line 863, in __call__
    raise self.mapping[code](*args, **kwargs)
werkzeug.exceptions.InternalServerError: 500 Internal Server Error: The server encountered an internal error and was unable to complete your request. Either the server is overloaded or there is an error in the application.
2024-08-04 11:29:41,147 - app - ERROR - Exception on /api/get-all-tenders [GET]
Traceback (most recent call last):
  File "D:\practicum\kostiner-tenders\kostiner-tenders-back\controllers\tender_controller.py", line 33, in get
    list_array = tender_service.get_all(user, search_date)
                 ^^^^^^^^^^^^^^^^^^^^^^^^^^^^^^^^^^^^^^^^^
  File "D:\practicum\kostiner-tenders\kostiner-tenders-back\services\tender_service.py", line 31, in get_all
    abort(500, 'user invalid')
  File "D:\practicum\kostiner-tenders\kostiner-tenders-back\.venv\Lib\site-packages\flask_restx\errors.py", line 28, in abort
    flask.abort(code)
  File "D:\practicum\kostiner-tenders\kostiner-tenders-back\.venv\Lib\site-packages\flask\helpers.py", line 272, in abort
    current_app.aborter(code, *args, **kwargs)
  File "D:\practicum\kostiner-tenders\kostiner-tenders-back\.venv\Lib\site-packages\werkzeug\exceptions.py", line 863, in __call__
    raise self.mapping[code](*args, **kwargs)
werkzeug.exceptions.InternalServerError: 500 Internal Server Error: The server encountered an internal error and was unable to complete your request. Either the server is overloaded or there is an error in the application.

During handling of the above exception, another exception occurred:

Traceback (most recent call last):
  File "D:\practicum\kostiner-tenders\kostiner-tenders-back\.venv\Lib\site-packages\flask\app.py", line 880, in full_dispatch_request
    rv = self.dispatch_request()
         ^^^^^^^^^^^^^^^^^^^^^^^
  File "D:\practicum\kostiner-tenders\kostiner-tenders-back\.venv\Lib\site-packages\flask\app.py", line 865, in dispatch_request
    return self.ensure_sync(self.view_functions[rule.endpoint])(**view_args)  # type: ignore[no-any-return]
           ^^^^^^^^^^^^^^^^^^^^^^^^^^^^^^^^^^^^^^^^^^^^^^^^^^^^^^^^^^^^^^^^^
  File "D:\practicum\kostiner-tenders\kostiner-tenders-back\.venv\Lib\site-packages\flask_restx\api.py", line 402, in wrapper
    resp = resource(*args, **kwargs)
           ^^^^^^^^^^^^^^^^^^^^^^^^^
  File "D:\practicum\kostiner-tenders\kostiner-tenders-back\.venv\Lib\site-packages\flask\views.py", line 110, in view
    return current_app.ensure_sync(self.dispatch_request)(**kwargs)  # type: ignore[no-any-return]
           ^^^^^^^^^^^^^^^^^^^^^^^^^^^^^^^^^^^^^^^^^^^^^^^^^^^^^^^^
  File "D:\practicum\kostiner-tenders\kostiner-tenders-back\.venv\Lib\site-packages\flask_restx\resource.py", line 41, in dispatch_request
    resp = meth(*args, **kwargs)
           ^^^^^^^^^^^^^^^^^^^^^
  File "D:\practicum\kostiner-tenders\kostiner-tenders-back\.venv\Lib\site-packages\flask_restx\marshalling.py", line 244, in wrapper
    resp = f(*args, **kwargs)
           ^^^^^^^^^^^^^^^^^^
  File "D:\practicum\kostiner-tenders\kostiner-tenders-back\.venv\Lib\site-packages\flask_jwt_extended\view_decorators.py", line 170, in decorator
    return current_app.ensure_sync(fn)(*args, **kwargs)
           ^^^^^^^^^^^^^^^^^^^^^^^^^^^^^^^^^^^^^^^^^^^^
  File "D:\practicum\kostiner-tenders\kostiner-tenders-back\controllers\tender_controller.py", line 47, in get
    abort(500, "message: Internal server error. Please contact support.")
  File "D:\practicum\kostiner-tenders\kostiner-tenders-back\.venv\Lib\site-packages\flask_restx\errors.py", line 28, in abort
    flask.abort(code)
  File "D:\practicum\kostiner-tenders\kostiner-tenders-back\.venv\Lib\site-packages\flask\helpers.py", line 272, in abort
    current_app.aborter(code, *args, **kwargs)
  File "D:\practicum\kostiner-tenders\kostiner-tenders-back\.venv\Lib\site-packages\werkzeug\exceptions.py", line 863, in __call__
    raise self.mapping[code](*args, **kwargs)
werkzeug.exceptions.InternalServerError: 500 Internal Server Error: The server encountered an internal error and was unable to complete your request. Either the server is overloaded or there is an error in the application.
2024-08-04 11:29:41,186 - werkzeug - INFO - 127.0.0.1 - - [04/Aug/2024 11:29:41] "[35m[1mGET /api/get-all-tenders HTTP/1.1[0m" 500 -
2024-08-04 11:35:51,362 - werkzeug - INFO - 127.0.0.1 - - [04/Aug/2024 11:35:51] "GET / HTTP/1.1" 200 -
2024-08-04 11:35:51,540 - werkzeug - INFO - 127.0.0.1 - - [04/Aug/2024 11:35:51] "[36mGET /swaggerui/droid-sans.css HTTP/1.1[0m" 304 -
2024-08-04 11:35:51,540 - werkzeug - INFO - 127.0.0.1 - - [04/Aug/2024 11:35:51] "[36mGET /swaggerui/swagger-ui-bundle.js HTTP/1.1[0m" 304 -
2024-08-04 11:35:51,547 - werkzeug - INFO - 127.0.0.1 - - [04/Aug/2024 11:35:51] "[36mGET /swaggerui/swagger-ui.css HTTP/1.1[0m" 304 -
2024-08-04 11:35:51,547 - werkzeug - INFO - 127.0.0.1 - - [04/Aug/2024 11:35:51] "[36mGET /swaggerui/swagger-ui-standalone-preset.js HTTP/1.1[0m" 304 -
2024-08-04 11:35:51,696 - werkzeug - INFO - 127.0.0.1 - - [04/Aug/2024 11:35:51] "GET /swagger.json HTTP/1.1" 200 -
2024-08-04 11:35:51,712 - werkzeug - INFO - 127.0.0.1 - - [04/Aug/2024 11:35:51] "[36mGET /swaggerui/favicon-32x32.png HTTP/1.1[0m" 304 -
2024-08-04 11:37:54,284 - werkzeug - INFO -  * Detected change in 'D:\\practicum\\kostiner-tenders\\kostiner-tenders-back\\controllers\\tender_controller.py', reloading
2024-08-04 11:37:54,927 - werkzeug - INFO -  * Restarting with stat
2024-08-04 11:38:52,239 - werkzeug - WARNING -  * Debugger is active!
2024-08-04 11:38:52,248 - werkzeug - INFO -  * Debugger PIN: 120-157-398
2024-08-04 11:39:24,183 - werkzeug - INFO -  * Detected change in 'D:\\practicum\\kostiner-tenders\\kostiner-tenders-back\\services\\tender_service.py', reloading
2024-08-04 11:39:24,851 - werkzeug - INFO -  * Restarting with stat
2024-08-04 11:40:03,811 - werkzeug - WARNING -  * Debugger is active!
2024-08-04 11:40:03,817 - werkzeug - INFO -  * Debugger PIN: 120-157-398
2024-08-04 11:41:32,876 - werkzeug - INFO -  * Detected change in 'D:\\practicum\\kostiner-tenders\\kostiner-tenders-back\\services\\tender_service.py', reloading
2024-08-04 11:41:33,484 - werkzeug - INFO -  * Restarting with stat
2024-08-04 11:41:50,794 - werkzeug - WARNING -  * Debugger is active!
2024-08-04 11:41:50,802 - werkzeug - INFO -  * Debugger PIN: 120-157-398
2024-08-04 11:42:52,555 - werkzeug - INFO - 127.0.0.1 - - [04/Aug/2024 11:42:52] "POST /auth/login HTTP/1.1" 200 -
2024-08-04 11:43:14,685 - root - INFO - tender service get_all category entertainment
2024-08-04 11:43:14,685 - root - INFO - query {'$and': [{'category': 'entertainment'}, {'published_date': {'$gte': datetime.datetime(2023, 7, 20, 0, 0)}}, {'published_date': {'$lte': None}}]}
2024-08-04 11:43:14,685 - root - ERROR - tender controller Exception msg: '>' not supported between instances of 'NoneType' and 'datetime.datetime'
2024-08-04 11:43:14,685 - app - ERROR - Exception on /api/get-all-tenders [GET]
Traceback (most recent call last):
  File "D:\practicum\kostiner-tenders\kostiner-tenders-back\controllers\tender_controller.py", line 33, in get
    list_array = tender_service.get_all(user, search_date)
                 ^^^^^^^^^^^^^^^^^^^^^^^^^^^^^^^^^^^^^^^^^
  File "D:\practicum\kostiner-tenders\kostiner-tenders-back\services\tender_service.py", line 95, in get_all
    add_tenders_by_categories(categories_history, new_search_date, purchase_start_date, purchase_end_date)
  File "D:\practicum\kostiner-tenders\kostiner-tenders-back\services\tender_service.py", line 88, in add_tenders_by_categories
    tender_list = self.repo.get_by_category(category, new_search_date, start_date, end_date)
                  ^^^^^^^^^^^^^^^^^^^^^^^^^^^^^^^^^^^^^^^^^^^^^^^^^^^^^^^^^^^^^^^^^^^^^^^^^^
  File "D:\practicum\kostiner-tenders\kostiner-tenders-back\dal\tender_repo.py", line 56, in get_by_category
    if search_date > start_date:
       ^^^^^^^^^^^^^^^^^^^^^^^^
TypeError: '>' not supported between instances of 'NoneType' and 'datetime.datetime'

During handling of the above exception, another exception occurred:

Traceback (most recent call last):
  File "D:\practicum\kostiner-tenders\kostiner-tenders-back\.venv\Lib\site-packages\flask\app.py", line 880, in full_dispatch_request
    rv = self.dispatch_request()
         ^^^^^^^^^^^^^^^^^^^^^^^
  File "D:\practicum\kostiner-tenders\kostiner-tenders-back\.venv\Lib\site-packages\flask\app.py", line 865, in dispatch_request
    return self.ensure_sync(self.view_functions[rule.endpoint])(**view_args)  # type: ignore[no-any-return]
           ^^^^^^^^^^^^^^^^^^^^^^^^^^^^^^^^^^^^^^^^^^^^^^^^^^^^^^^^^^^^^^^^^
  File "D:\practicum\kostiner-tenders\kostiner-tenders-back\.venv\Lib\site-packages\flask_restx\api.py", line 402, in wrapper
    resp = resource(*args, **kwargs)
           ^^^^^^^^^^^^^^^^^^^^^^^^^
  File "D:\practicum\kostiner-tenders\kostiner-tenders-back\.venv\Lib\site-packages\flask\views.py", line 110, in view
    return current_app.ensure_sync(self.dispatch_request)(**kwargs)  # type: ignore[no-any-return]
           ^^^^^^^^^^^^^^^^^^^^^^^^^^^^^^^^^^^^^^^^^^^^^^^^^^^^^^^^
  File "D:\practicum\kostiner-tenders\kostiner-tenders-back\.venv\Lib\site-packages\flask_restx\resource.py", line 41, in dispatch_request
    resp = meth(*args, **kwargs)
           ^^^^^^^^^^^^^^^^^^^^^
  File "D:\practicum\kostiner-tenders\kostiner-tenders-back\.venv\Lib\site-packages\flask_restx\marshalling.py", line 244, in wrapper
    resp = f(*args, **kwargs)
           ^^^^^^^^^^^^^^^^^^
  File "D:\practicum\kostiner-tenders\kostiner-tenders-back\.venv\Lib\site-packages\flask_jwt_extended\view_decorators.py", line 170, in decorator
    return current_app.ensure_sync(fn)(*args, **kwargs)
           ^^^^^^^^^^^^^^^^^^^^^^^^^^^^^^^^^^^^^^^^^^^^
  File "D:\practicum\kostiner-tenders\kostiner-tenders-back\controllers\tender_controller.py", line 47, in get
    abort(500, "message: Internal server error. Please contact support.")
  File "D:\practicum\kostiner-tenders\kostiner-tenders-back\.venv\Lib\site-packages\flask_restx\errors.py", line 28, in abort
    flask.abort(code)
  File "D:\practicum\kostiner-tenders\kostiner-tenders-back\.venv\Lib\site-packages\flask\helpers.py", line 272, in abort
    current_app.aborter(code, *args, **kwargs)
  File "D:\practicum\kostiner-tenders\kostiner-tenders-back\.venv\Lib\site-packages\werkzeug\exceptions.py", line 863, in __call__
    raise self.mapping[code](*args, **kwargs)
werkzeug.exceptions.InternalServerError: 500 Internal Server Error: The server encountered an internal error and was unable to complete your request. Either the server is overloaded or there is an error in the application.
2024-08-04 11:43:14,685 - app - ERROR - Exception on /api/get-all-tenders [GET]
Traceback (most recent call last):
  File "D:\practicum\kostiner-tenders\kostiner-tenders-back\controllers\tender_controller.py", line 33, in get
    list_array = tender_service.get_all(user, search_date)
                 ^^^^^^^^^^^^^^^^^^^^^^^^^^^^^^^^^^^^^^^^^
  File "D:\practicum\kostiner-tenders\kostiner-tenders-back\services\tender_service.py", line 95, in get_all
    add_tenders_by_categories(categories_history, new_search_date, purchase_start_date, purchase_end_date)
  File "D:\practicum\kostiner-tenders\kostiner-tenders-back\services\tender_service.py", line 88, in add_tenders_by_categories
    tender_list = self.repo.get_by_category(category, new_search_date, start_date, end_date)
                  ^^^^^^^^^^^^^^^^^^^^^^^^^^^^^^^^^^^^^^^^^^^^^^^^^^^^^^^^^^^^^^^^^^^^^^^^^^
  File "D:\practicum\kostiner-tenders\kostiner-tenders-back\dal\tender_repo.py", line 56, in get_by_category
    if search_date > start_date:
       ^^^^^^^^^^^^^^^^^^^^^^^^
TypeError: '>' not supported between instances of 'NoneType' and 'datetime.datetime'

During handling of the above exception, another exception occurred:

Traceback (most recent call last):
  File "D:\practicum\kostiner-tenders\kostiner-tenders-back\.venv\Lib\site-packages\flask\app.py", line 880, in full_dispatch_request
    rv = self.dispatch_request()
         ^^^^^^^^^^^^^^^^^^^^^^^
  File "D:\practicum\kostiner-tenders\kostiner-tenders-back\.venv\Lib\site-packages\flask\app.py", line 865, in dispatch_request
    return self.ensure_sync(self.view_functions[rule.endpoint])(**view_args)  # type: ignore[no-any-return]
           ^^^^^^^^^^^^^^^^^^^^^^^^^^^^^^^^^^^^^^^^^^^^^^^^^^^^^^^^^^^^^^^^^
  File "D:\practicum\kostiner-tenders\kostiner-tenders-back\.venv\Lib\site-packages\flask_restx\api.py", line 402, in wrapper
    resp = resource(*args, **kwargs)
           ^^^^^^^^^^^^^^^^^^^^^^^^^
  File "D:\practicum\kostiner-tenders\kostiner-tenders-back\.venv\Lib\site-packages\flask\views.py", line 110, in view
    return current_app.ensure_sync(self.dispatch_request)(**kwargs)  # type: ignore[no-any-return]
           ^^^^^^^^^^^^^^^^^^^^^^^^^^^^^^^^^^^^^^^^^^^^^^^^^^^^^^^^
  File "D:\practicum\kostiner-tenders\kostiner-tenders-back\.venv\Lib\site-packages\flask_restx\resource.py", line 41, in dispatch_request
    resp = meth(*args, **kwargs)
           ^^^^^^^^^^^^^^^^^^^^^
  File "D:\practicum\kostiner-tenders\kostiner-tenders-back\.venv\Lib\site-packages\flask_restx\marshalling.py", line 244, in wrapper
    resp = f(*args, **kwargs)
           ^^^^^^^^^^^^^^^^^^
  File "D:\practicum\kostiner-tenders\kostiner-tenders-back\.venv\Lib\site-packages\flask_jwt_extended\view_decorators.py", line 170, in decorator
    return current_app.ensure_sync(fn)(*args, **kwargs)
           ^^^^^^^^^^^^^^^^^^^^^^^^^^^^^^^^^^^^^^^^^^^^
  File "D:\practicum\kostiner-tenders\kostiner-tenders-back\controllers\tender_controller.py", line 47, in get
    abort(500, "message: Internal server error. Please contact support.")
  File "D:\practicum\kostiner-tenders\kostiner-tenders-back\.venv\Lib\site-packages\flask_restx\errors.py", line 28, in abort
    flask.abort(code)
  File "D:\practicum\kostiner-tenders\kostiner-tenders-back\.venv\Lib\site-packages\flask\helpers.py", line 272, in abort
    current_app.aborter(code, *args, **kwargs)
  File "D:\practicum\kostiner-tenders\kostiner-tenders-back\.venv\Lib\site-packages\werkzeug\exceptions.py", line 863, in __call__
    raise self.mapping[code](*args, **kwargs)
werkzeug.exceptions.InternalServerError: 500 Internal Server Error: The server encountered an internal error and was unable to complete your request. Either the server is overloaded or there is an error in the application.
2024-08-04 11:43:14,774 - werkzeug - INFO - 127.0.0.1 - - [04/Aug/2024 11:43:14] "[35m[1mGET /api/get-all-tenders HTTP/1.1[0m" 500 -
2024-08-04 11:48:51,473 - werkzeug - INFO -  * Detected change in 'D:\\practicum\\kostiner-tenders\\kostiner-tenders-back\\services\\tender_service.py', reloading
2024-08-04 11:48:52,064 - werkzeug - INFO -  * Restarting with stat
2024-08-04 11:49:06,479 - werkzeug - WARNING -  * Debugger is active!
2024-08-04 11:49:06,484 - werkzeug - INFO -  * Debugger PIN: 120-157-398
2024-08-04 11:50:00,261 - root - ERROR - tender controller Exception msg: 400 Bad Request: The browser (or proxy) sent a request that this server could not understand.
2024-08-04 11:50:00,261 - app - ERROR - Exception on /api/get-all-tenders [GET]
Traceback (most recent call last):
  File "D:\practicum\kostiner-tenders\kostiner-tenders-back\controllers\tender_controller.py", line 33, in get
    list_array = tender_service.get_all(user, search_date)
                 ^^^^^^^^^^^^^^^^^^^^^^^^^^^^^^^^^^^^^^^^^
  File "D:\practicum\kostiner-tenders\kostiner-tenders-back\services\tender_service.py", line 59, in get_all
    purchase_end_date = parse_date(purchase.get('purchase_end_date  or missing data'),
                        ^^^^^^^^^^^^^^^^^^^^^^^^^^^^^^^^^^^^^^^^^^^^^^^^^^^^^^^^^^^^^^
  File "D:\practicum\kostiner-tenders\kostiner-tenders-back\services\tender_service.py", line 41, in parse_date
    abort(400, 'missing data')
  File "D:\practicum\kostiner-tenders\kostiner-tenders-back\.venv\Lib\site-packages\flask_restx\errors.py", line 28, in abort
    flask.abort(code)
  File "D:\practicum\kostiner-tenders\kostiner-tenders-back\.venv\Lib\site-packages\flask\helpers.py", line 272, in abort
    current_app.aborter(code, *args, **kwargs)
  File "D:\practicum\kostiner-tenders\kostiner-tenders-back\.venv\Lib\site-packages\werkzeug\exceptions.py", line 863, in __call__
    raise self.mapping[code](*args, **kwargs)
werkzeug.exceptions.BadRequest: 400 Bad Request: The browser (or proxy) sent a request that this server could not understand.

During handling of the above exception, another exception occurred:

Traceback (most recent call last):
  File "D:\practicum\kostiner-tenders\kostiner-tenders-back\.venv\Lib\site-packages\flask\app.py", line 880, in full_dispatch_request
    rv = self.dispatch_request()
         ^^^^^^^^^^^^^^^^^^^^^^^
  File "D:\practicum\kostiner-tenders\kostiner-tenders-back\.venv\Lib\site-packages\flask\app.py", line 865, in dispatch_request
    return self.ensure_sync(self.view_functions[rule.endpoint])(**view_args)  # type: ignore[no-any-return]
           ^^^^^^^^^^^^^^^^^^^^^^^^^^^^^^^^^^^^^^^^^^^^^^^^^^^^^^^^^^^^^^^^^
  File "D:\practicum\kostiner-tenders\kostiner-tenders-back\.venv\Lib\site-packages\flask_restx\api.py", line 402, in wrapper
    resp = resource(*args, **kwargs)
           ^^^^^^^^^^^^^^^^^^^^^^^^^
  File "D:\practicum\kostiner-tenders\kostiner-tenders-back\.venv\Lib\site-packages\flask\views.py", line 110, in view
    return current_app.ensure_sync(self.dispatch_request)(**kwargs)  # type: ignore[no-any-return]
           ^^^^^^^^^^^^^^^^^^^^^^^^^^^^^^^^^^^^^^^^^^^^^^^^^^^^^^^^
  File "D:\practicum\kostiner-tenders\kostiner-tenders-back\.venv\Lib\site-packages\flask_restx\resource.py", line 41, in dispatch_request
    resp = meth(*args, **kwargs)
           ^^^^^^^^^^^^^^^^^^^^^
  File "D:\practicum\kostiner-tenders\kostiner-tenders-back\.venv\Lib\site-packages\flask_restx\marshalling.py", line 244, in wrapper
    resp = f(*args, **kwargs)
           ^^^^^^^^^^^^^^^^^^
  File "D:\practicum\kostiner-tenders\kostiner-tenders-back\.venv\Lib\site-packages\flask_jwt_extended\view_decorators.py", line 170, in decorator
    return current_app.ensure_sync(fn)(*args, **kwargs)
           ^^^^^^^^^^^^^^^^^^^^^^^^^^^^^^^^^^^^^^^^^^^^
  File "D:\practicum\kostiner-tenders\kostiner-tenders-back\controllers\tender_controller.py", line 47, in get
    abort(500, "message: Internal server error. Please contact support.")
  File "D:\practicum\kostiner-tenders\kostiner-tenders-back\.venv\Lib\site-packages\flask_restx\errors.py", line 28, in abort
    flask.abort(code)
  File "D:\practicum\kostiner-tenders\kostiner-tenders-back\.venv\Lib\site-packages\flask\helpers.py", line 272, in abort
    current_app.aborter(code, *args, **kwargs)
  File "D:\practicum\kostiner-tenders\kostiner-tenders-back\.venv\Lib\site-packages\werkzeug\exceptions.py", line 863, in __call__
    raise self.mapping[code](*args, **kwargs)
werkzeug.exceptions.InternalServerError: 500 Internal Server Error: The server encountered an internal error and was unable to complete your request. Either the server is overloaded or there is an error in the application.
2024-08-04 11:50:00,261 - app - ERROR - Exception on /api/get-all-tenders [GET]
Traceback (most recent call last):
  File "D:\practicum\kostiner-tenders\kostiner-tenders-back\controllers\tender_controller.py", line 33, in get
    list_array = tender_service.get_all(user, search_date)
                 ^^^^^^^^^^^^^^^^^^^^^^^^^^^^^^^^^^^^^^^^^
  File "D:\practicum\kostiner-tenders\kostiner-tenders-back\services\tender_service.py", line 59, in get_all
    purchase_end_date = parse_date(purchase.get('purchase_end_date  or missing data'),
                        ^^^^^^^^^^^^^^^^^^^^^^^^^^^^^^^^^^^^^^^^^^^^^^^^^^^^^^^^^^^^^^
  File "D:\practicum\kostiner-tenders\kostiner-tenders-back\services\tender_service.py", line 41, in parse_date
    abort(400, 'missing data')
  File "D:\practicum\kostiner-tenders\kostiner-tenders-back\.venv\Lib\site-packages\flask_restx\errors.py", line 28, in abort
    flask.abort(code)
  File "D:\practicum\kostiner-tenders\kostiner-tenders-back\.venv\Lib\site-packages\flask\helpers.py", line 272, in abort
    current_app.aborter(code, *args, **kwargs)
  File "D:\practicum\kostiner-tenders\kostiner-tenders-back\.venv\Lib\site-packages\werkzeug\exceptions.py", line 863, in __call__
    raise self.mapping[code](*args, **kwargs)
werkzeug.exceptions.BadRequest: 400 Bad Request: The browser (or proxy) sent a request that this server could not understand.

During handling of the above exception, another exception occurred:

Traceback (most recent call last):
  File "D:\practicum\kostiner-tenders\kostiner-tenders-back\.venv\Lib\site-packages\flask\app.py", line 880, in full_dispatch_request
    rv = self.dispatch_request()
         ^^^^^^^^^^^^^^^^^^^^^^^
  File "D:\practicum\kostiner-tenders\kostiner-tenders-back\.venv\Lib\site-packages\flask\app.py", line 865, in dispatch_request
    return self.ensure_sync(self.view_functions[rule.endpoint])(**view_args)  # type: ignore[no-any-return]
           ^^^^^^^^^^^^^^^^^^^^^^^^^^^^^^^^^^^^^^^^^^^^^^^^^^^^^^^^^^^^^^^^^
  File "D:\practicum\kostiner-tenders\kostiner-tenders-back\.venv\Lib\site-packages\flask_restx\api.py", line 402, in wrapper
    resp = resource(*args, **kwargs)
           ^^^^^^^^^^^^^^^^^^^^^^^^^
  File "D:\practicum\kostiner-tenders\kostiner-tenders-back\.venv\Lib\site-packages\flask\views.py", line 110, in view
    return current_app.ensure_sync(self.dispatch_request)(**kwargs)  # type: ignore[no-any-return]
           ^^^^^^^^^^^^^^^^^^^^^^^^^^^^^^^^^^^^^^^^^^^^^^^^^^^^^^^^
  File "D:\practicum\kostiner-tenders\kostiner-tenders-back\.venv\Lib\site-packages\flask_restx\resource.py", line 41, in dispatch_request
    resp = meth(*args, **kwargs)
           ^^^^^^^^^^^^^^^^^^^^^
  File "D:\practicum\kostiner-tenders\kostiner-tenders-back\.venv\Lib\site-packages\flask_restx\marshalling.py", line 244, in wrapper
    resp = f(*args, **kwargs)
           ^^^^^^^^^^^^^^^^^^
  File "D:\practicum\kostiner-tenders\kostiner-tenders-back\.venv\Lib\site-packages\flask_jwt_extended\view_decorators.py", line 170, in decorator
    return current_app.ensure_sync(fn)(*args, **kwargs)
           ^^^^^^^^^^^^^^^^^^^^^^^^^^^^^^^^^^^^^^^^^^^^
  File "D:\practicum\kostiner-tenders\kostiner-tenders-back\controllers\tender_controller.py", line 47, in get
    abort(500, "message: Internal server error. Please contact support.")
  File "D:\practicum\kostiner-tenders\kostiner-tenders-back\.venv\Lib\site-packages\flask_restx\errors.py", line 28, in abort
    flask.abort(code)
  File "D:\practicum\kostiner-tenders\kostiner-tenders-back\.venv\Lib\site-packages\flask\helpers.py", line 272, in abort
    current_app.aborter(code, *args, **kwargs)
  File "D:\practicum\kostiner-tenders\kostiner-tenders-back\.venv\Lib\site-packages\werkzeug\exceptions.py", line 863, in __call__
    raise self.mapping[code](*args, **kwargs)
werkzeug.exceptions.InternalServerError: 500 Internal Server Error: The server encountered an internal error and was unable to complete your request. Either the server is overloaded or there is an error in the application.
2024-08-04 11:50:00,284 - werkzeug - INFO - 127.0.0.1 - - [04/Aug/2024 11:50:00] "[35m[1mGET /api/get-all-tenders HTTP/1.1[0m" 500 -
2024-08-04 11:57:55,308 - werkzeug - INFO -  * Detected change in 'D:\\practicum\\kostiner-tenders\\kostiner-tenders-back\\app\\app.py', reloading
2024-08-04 11:57:55,831 - werkzeug - INFO -  * Restarting with stat
2024-08-04 11:58:15,829 - werkzeug - WARNING -  * Debugger is active!
2024-08-04 11:58:15,835 - werkzeug - INFO -  * Debugger PIN: 120-157-398
2024-08-04 12:00:18,781 - werkzeug - INFO - 127.0.0.1 - - [04/Aug/2024 12:00:18] "[31m[1mGET /api/get-all-tenders HTTP/1.1[0m" 401 -
2024-08-04 12:00:23,659 - werkzeug - INFO - 127.0.0.1 - - [04/Aug/2024 12:00:23] "POST /auth/login HTTP/1.1" 200 -
2024-08-04 12:00:43,246 - root - ERROR - tender controller Exception msg: 400 Bad Request: The browser (or proxy) sent a request that this server could not understand.
2024-08-04 12:00:43,246 - app - ERROR - Exception on /api/get-all-tenders [GET]
Traceback (most recent call last):
  File "D:\practicum\kostiner-tenders\kostiner-tenders-back\controllers\tender_controller.py", line 33, in get
    list_array = tender_service.get_all(user, search_date)
                 ^^^^^^^^^^^^^^^^^^^^^^^^^^^^^^^^^^^^^^^^^
  File "D:\practicum\kostiner-tenders\kostiner-tenders-back\services\tender_service.py", line 59, in get_all
    purchase_end_date = parse_date(purchase.get('purchase_end_date  or missing data'),
                        ^^^^^^^^^^^^^^^^^^^^^^^^^^^^^^^^^^^^^^^^^^^^^^^^^^^^^^^^^^^^^^
  File "D:\practicum\kostiner-tenders\kostiner-tenders-back\services\tender_service.py", line 41, in parse_date
    abort(400, 'missing data')
  File "D:\practicum\kostiner-tenders\kostiner-tenders-back\.venv\Lib\site-packages\flask_restx\errors.py", line 28, in abort
    flask.abort(code)
  File "D:\practicum\kostiner-tenders\kostiner-tenders-back\.venv\Lib\site-packages\flask\helpers.py", line 272, in abort
    current_app.aborter(code, *args, **kwargs)
  File "D:\practicum\kostiner-tenders\kostiner-tenders-back\.venv\Lib\site-packages\werkzeug\exceptions.py", line 863, in __call__
    raise self.mapping[code](*args, **kwargs)
werkzeug.exceptions.BadRequest: 400 Bad Request: The browser (or proxy) sent a request that this server could not understand.

During handling of the above exception, another exception occurred:

Traceback (most recent call last):
  File "D:\practicum\kostiner-tenders\kostiner-tenders-back\.venv\Lib\site-packages\flask\app.py", line 880, in full_dispatch_request
    rv = self.dispatch_request()
         ^^^^^^^^^^^^^^^^^^^^^^^
  File "D:\practicum\kostiner-tenders\kostiner-tenders-back\.venv\Lib\site-packages\flask\app.py", line 865, in dispatch_request
    return self.ensure_sync(self.view_functions[rule.endpoint])(**view_args)  # type: ignore[no-any-return]
           ^^^^^^^^^^^^^^^^^^^^^^^^^^^^^^^^^^^^^^^^^^^^^^^^^^^^^^^^^^^^^^^^^
  File "D:\practicum\kostiner-tenders\kostiner-tenders-back\.venv\Lib\site-packages\flask_restx\api.py", line 402, in wrapper
    resp = resource(*args, **kwargs)
           ^^^^^^^^^^^^^^^^^^^^^^^^^
  File "D:\practicum\kostiner-tenders\kostiner-tenders-back\.venv\Lib\site-packages\flask\views.py", line 110, in view
    return current_app.ensure_sync(self.dispatch_request)(**kwargs)  # type: ignore[no-any-return]
           ^^^^^^^^^^^^^^^^^^^^^^^^^^^^^^^^^^^^^^^^^^^^^^^^^^^^^^^^
  File "D:\practicum\kostiner-tenders\kostiner-tenders-back\.venv\Lib\site-packages\flask_restx\resource.py", line 41, in dispatch_request
    resp = meth(*args, **kwargs)
           ^^^^^^^^^^^^^^^^^^^^^
  File "D:\practicum\kostiner-tenders\kostiner-tenders-back\.venv\Lib\site-packages\flask_restx\marshalling.py", line 244, in wrapper
    resp = f(*args, **kwargs)
           ^^^^^^^^^^^^^^^^^^
  File "D:\practicum\kostiner-tenders\kostiner-tenders-back\.venv\Lib\site-packages\flask_jwt_extended\view_decorators.py", line 170, in decorator
    return current_app.ensure_sync(fn)(*args, **kwargs)
           ^^^^^^^^^^^^^^^^^^^^^^^^^^^^^^^^^^^^^^^^^^^^
  File "D:\practicum\kostiner-tenders\kostiner-tenders-back\controllers\tender_controller.py", line 47, in get
    abort(500, "message: Internal server error. Please contact support.")
  File "D:\practicum\kostiner-tenders\kostiner-tenders-back\.venv\Lib\site-packages\flask_restx\errors.py", line 28, in abort
    flask.abort(code)
  File "D:\practicum\kostiner-tenders\kostiner-tenders-back\.venv\Lib\site-packages\flask\helpers.py", line 272, in abort
    current_app.aborter(code, *args, **kwargs)
  File "D:\practicum\kostiner-tenders\kostiner-tenders-back\.venv\Lib\site-packages\werkzeug\exceptions.py", line 863, in __call__
    raise self.mapping[code](*args, **kwargs)
werkzeug.exceptions.InternalServerError: 500 Internal Server Error: The server encountered an internal error and was unable to complete your request. Either the server is overloaded or there is an error in the application.
2024-08-04 12:00:43,246 - app - ERROR - Exception on /api/get-all-tenders [GET]
Traceback (most recent call last):
  File "D:\practicum\kostiner-tenders\kostiner-tenders-back\controllers\tender_controller.py", line 33, in get
    list_array = tender_service.get_all(user, search_date)
                 ^^^^^^^^^^^^^^^^^^^^^^^^^^^^^^^^^^^^^^^^^
  File "D:\practicum\kostiner-tenders\kostiner-tenders-back\services\tender_service.py", line 59, in get_all
    purchase_end_date = parse_date(purchase.get('purchase_end_date  or missing data'),
                        ^^^^^^^^^^^^^^^^^^^^^^^^^^^^^^^^^^^^^^^^^^^^^^^^^^^^^^^^^^^^^^
  File "D:\practicum\kostiner-tenders\kostiner-tenders-back\services\tender_service.py", line 41, in parse_date
    abort(400, 'missing data')
  File "D:\practicum\kostiner-tenders\kostiner-tenders-back\.venv\Lib\site-packages\flask_restx\errors.py", line 28, in abort
    flask.abort(code)
  File "D:\practicum\kostiner-tenders\kostiner-tenders-back\.venv\Lib\site-packages\flask\helpers.py", line 272, in abort
    current_app.aborter(code, *args, **kwargs)
  File "D:\practicum\kostiner-tenders\kostiner-tenders-back\.venv\Lib\site-packages\werkzeug\exceptions.py", line 863, in __call__
    raise self.mapping[code](*args, **kwargs)
werkzeug.exceptions.BadRequest: 400 Bad Request: The browser (or proxy) sent a request that this server could not understand.

During handling of the above exception, another exception occurred:

Traceback (most recent call last):
  File "D:\practicum\kostiner-tenders\kostiner-tenders-back\.venv\Lib\site-packages\flask\app.py", line 880, in full_dispatch_request
    rv = self.dispatch_request()
         ^^^^^^^^^^^^^^^^^^^^^^^
  File "D:\practicum\kostiner-tenders\kostiner-tenders-back\.venv\Lib\site-packages\flask\app.py", line 865, in dispatch_request
    return self.ensure_sync(self.view_functions[rule.endpoint])(**view_args)  # type: ignore[no-any-return]
           ^^^^^^^^^^^^^^^^^^^^^^^^^^^^^^^^^^^^^^^^^^^^^^^^^^^^^^^^^^^^^^^^^
  File "D:\practicum\kostiner-tenders\kostiner-tenders-back\.venv\Lib\site-packages\flask_restx\api.py", line 402, in wrapper
    resp = resource(*args, **kwargs)
           ^^^^^^^^^^^^^^^^^^^^^^^^^
  File "D:\practicum\kostiner-tenders\kostiner-tenders-back\.venv\Lib\site-packages\flask\views.py", line 110, in view
    return current_app.ensure_sync(self.dispatch_request)(**kwargs)  # type: ignore[no-any-return]
           ^^^^^^^^^^^^^^^^^^^^^^^^^^^^^^^^^^^^^^^^^^^^^^^^^^^^^^^^
  File "D:\practicum\kostiner-tenders\kostiner-tenders-back\.venv\Lib\site-packages\flask_restx\resource.py", line 41, in dispatch_request
    resp = meth(*args, **kwargs)
           ^^^^^^^^^^^^^^^^^^^^^
  File "D:\practicum\kostiner-tenders\kostiner-tenders-back\.venv\Lib\site-packages\flask_restx\marshalling.py", line 244, in wrapper
    resp = f(*args, **kwargs)
           ^^^^^^^^^^^^^^^^^^
  File "D:\practicum\kostiner-tenders\kostiner-tenders-back\.venv\Lib\site-packages\flask_jwt_extended\view_decorators.py", line 170, in decorator
    return current_app.ensure_sync(fn)(*args, **kwargs)
           ^^^^^^^^^^^^^^^^^^^^^^^^^^^^^^^^^^^^^^^^^^^^
  File "D:\practicum\kostiner-tenders\kostiner-tenders-back\controllers\tender_controller.py", line 47, in get
    abort(500, "message: Internal server error. Please contact support.")
  File "D:\practicum\kostiner-tenders\kostiner-tenders-back\.venv\Lib\site-packages\flask_restx\errors.py", line 28, in abort
    flask.abort(code)
  File "D:\practicum\kostiner-tenders\kostiner-tenders-back\.venv\Lib\site-packages\flask\helpers.py", line 272, in abort
    current_app.aborter(code, *args, **kwargs)
  File "D:\practicum\kostiner-tenders\kostiner-tenders-back\.venv\Lib\site-packages\werkzeug\exceptions.py", line 863, in __call__
    raise self.mapping[code](*args, **kwargs)
werkzeug.exceptions.InternalServerError: 500 Internal Server Error: The server encountered an internal error and was unable to complete your request. Either the server is overloaded or there is an error in the application.
2024-08-04 12:00:43,274 - werkzeug - INFO - 127.0.0.1 - - [04/Aug/2024 12:00:43] "[35m[1mGET /api/get-all-tenders HTTP/1.1[0m" 500 -
2024-08-04 12:05:03,427 - root - ERROR - tender controller Exception msg: 400 Bad Request: The browser (or proxy) sent a request that this server could not understand.
2024-08-04 12:05:03,427 - app - ERROR - Exception on /api/get-all-tenders [GET]
Traceback (most recent call last):
  File "D:\practicum\kostiner-tenders\kostiner-tenders-back\controllers\tender_controller.py", line 33, in get
    list_array = tender_service.get_all(user, search_date)
                 ^^^^^^^^^^^^^^^^^^^^^^^^^^^^^^^^^^^^^^^^^
  File "D:\practicum\kostiner-tenders\kostiner-tenders-back\services\tender_service.py", line 59, in get_all
    purchase_end_date = parse_date(purchase.get('purchase_end_date  or missing data'),
                        ^^^^^^^^^^^^^^^^^^^^^^^^^^^^^^^^^^^^^^^^^^^^^^^^^^^^^^^^^^^^^^
  File "D:\practicum\kostiner-tenders\kostiner-tenders-back\services\tender_service.py", line 41, in parse_date
    abort(400, 'missing data')
  File "D:\practicum\kostiner-tenders\kostiner-tenders-back\.venv\Lib\site-packages\flask_restx\errors.py", line 28, in abort
    flask.abort(code)
  File "D:\practicum\kostiner-tenders\kostiner-tenders-back\.venv\Lib\site-packages\flask\helpers.py", line 272, in abort
    current_app.aborter(code, *args, **kwargs)
  File "D:\practicum\kostiner-tenders\kostiner-tenders-back\.venv\Lib\site-packages\werkzeug\exceptions.py", line 863, in __call__
    raise self.mapping[code](*args, **kwargs)
werkzeug.exceptions.BadRequest: 400 Bad Request: The browser (or proxy) sent a request that this server could not understand.

During handling of the above exception, another exception occurred:

Traceback (most recent call last):
  File "D:\practicum\kostiner-tenders\kostiner-tenders-back\.venv\Lib\site-packages\flask\app.py", line 880, in full_dispatch_request
    rv = self.dispatch_request()
         ^^^^^^^^^^^^^^^^^^^^^^^
  File "D:\practicum\kostiner-tenders\kostiner-tenders-back\.venv\Lib\site-packages\flask\app.py", line 865, in dispatch_request
    return self.ensure_sync(self.view_functions[rule.endpoint])(**view_args)  # type: ignore[no-any-return]
           ^^^^^^^^^^^^^^^^^^^^^^^^^^^^^^^^^^^^^^^^^^^^^^^^^^^^^^^^^^^^^^^^^
  File "D:\practicum\kostiner-tenders\kostiner-tenders-back\.venv\Lib\site-packages\flask_restx\api.py", line 402, in wrapper
    resp = resource(*args, **kwargs)
           ^^^^^^^^^^^^^^^^^^^^^^^^^
  File "D:\practicum\kostiner-tenders\kostiner-tenders-back\.venv\Lib\site-packages\flask\views.py", line 110, in view
    return current_app.ensure_sync(self.dispatch_request)(**kwargs)  # type: ignore[no-any-return]
           ^^^^^^^^^^^^^^^^^^^^^^^^^^^^^^^^^^^^^^^^^^^^^^^^^^^^^^^^
  File "D:\practicum\kostiner-tenders\kostiner-tenders-back\.venv\Lib\site-packages\flask_restx\resource.py", line 41, in dispatch_request
    resp = meth(*args, **kwargs)
           ^^^^^^^^^^^^^^^^^^^^^
  File "D:\practicum\kostiner-tenders\kostiner-tenders-back\.venv\Lib\site-packages\flask_restx\marshalling.py", line 244, in wrapper
    resp = f(*args, **kwargs)
           ^^^^^^^^^^^^^^^^^^
  File "D:\practicum\kostiner-tenders\kostiner-tenders-back\.venv\Lib\site-packages\flask_jwt_extended\view_decorators.py", line 170, in decorator
    return current_app.ensure_sync(fn)(*args, **kwargs)
           ^^^^^^^^^^^^^^^^^^^^^^^^^^^^^^^^^^^^^^^^^^^^
  File "D:\practicum\kostiner-tenders\kostiner-tenders-back\controllers\tender_controller.py", line 47, in get
    abort(500, "message: Internal server error. Please contact support.")
  File "D:\practicum\kostiner-tenders\kostiner-tenders-back\.venv\Lib\site-packages\flask_restx\errors.py", line 28, in abort
    flask.abort(code)
  File "D:\practicum\kostiner-tenders\kostiner-tenders-back\.venv\Lib\site-packages\flask\helpers.py", line 272, in abort
    current_app.aborter(code, *args, **kwargs)
  File "D:\practicum\kostiner-tenders\kostiner-tenders-back\.venv\Lib\site-packages\werkzeug\exceptions.py", line 863, in __call__
    raise self.mapping[code](*args, **kwargs)
werkzeug.exceptions.InternalServerError: 500 Internal Server Error: The server encountered an internal error and was unable to complete your request. Either the server is overloaded or there is an error in the application.
2024-08-04 12:05:03,427 - app - ERROR - Exception on /api/get-all-tenders [GET]
Traceback (most recent call last):
  File "D:\practicum\kostiner-tenders\kostiner-tenders-back\controllers\tender_controller.py", line 33, in get
    list_array = tender_service.get_all(user, search_date)
                 ^^^^^^^^^^^^^^^^^^^^^^^^^^^^^^^^^^^^^^^^^
  File "D:\practicum\kostiner-tenders\kostiner-tenders-back\services\tender_service.py", line 59, in get_all
    purchase_end_date = parse_date(purchase.get('purchase_end_date  or missing data'),
                        ^^^^^^^^^^^^^^^^^^^^^^^^^^^^^^^^^^^^^^^^^^^^^^^^^^^^^^^^^^^^^^
  File "D:\practicum\kostiner-tenders\kostiner-tenders-back\services\tender_service.py", line 41, in parse_date
    abort(400, 'missing data')
  File "D:\practicum\kostiner-tenders\kostiner-tenders-back\.venv\Lib\site-packages\flask_restx\errors.py", line 28, in abort
    flask.abort(code)
  File "D:\practicum\kostiner-tenders\kostiner-tenders-back\.venv\Lib\site-packages\flask\helpers.py", line 272, in abort
    current_app.aborter(code, *args, **kwargs)
  File "D:\practicum\kostiner-tenders\kostiner-tenders-back\.venv\Lib\site-packages\werkzeug\exceptions.py", line 863, in __call__
    raise self.mapping[code](*args, **kwargs)
werkzeug.exceptions.BadRequest: 400 Bad Request: The browser (or proxy) sent a request that this server could not understand.

During handling of the above exception, another exception occurred:

Traceback (most recent call last):
  File "D:\practicum\kostiner-tenders\kostiner-tenders-back\.venv\Lib\site-packages\flask\app.py", line 880, in full_dispatch_request
    rv = self.dispatch_request()
         ^^^^^^^^^^^^^^^^^^^^^^^
  File "D:\practicum\kostiner-tenders\kostiner-tenders-back\.venv\Lib\site-packages\flask\app.py", line 865, in dispatch_request
    return self.ensure_sync(self.view_functions[rule.endpoint])(**view_args)  # type: ignore[no-any-return]
           ^^^^^^^^^^^^^^^^^^^^^^^^^^^^^^^^^^^^^^^^^^^^^^^^^^^^^^^^^^^^^^^^^
  File "D:\practicum\kostiner-tenders\kostiner-tenders-back\.venv\Lib\site-packages\flask_restx\api.py", line 402, in wrapper
    resp = resource(*args, **kwargs)
           ^^^^^^^^^^^^^^^^^^^^^^^^^
  File "D:\practicum\kostiner-tenders\kostiner-tenders-back\.venv\Lib\site-packages\flask\views.py", line 110, in view
    return current_app.ensure_sync(self.dispatch_request)(**kwargs)  # type: ignore[no-any-return]
           ^^^^^^^^^^^^^^^^^^^^^^^^^^^^^^^^^^^^^^^^^^^^^^^^^^^^^^^^
  File "D:\practicum\kostiner-tenders\kostiner-tenders-back\.venv\Lib\site-packages\flask_restx\resource.py", line 41, in dispatch_request
    resp = meth(*args, **kwargs)
           ^^^^^^^^^^^^^^^^^^^^^
  File "D:\practicum\kostiner-tenders\kostiner-tenders-back\.venv\Lib\site-packages\flask_restx\marshalling.py", line 244, in wrapper
    resp = f(*args, **kwargs)
           ^^^^^^^^^^^^^^^^^^
  File "D:\practicum\kostiner-tenders\kostiner-tenders-back\.venv\Lib\site-packages\flask_jwt_extended\view_decorators.py", line 170, in decorator
    return current_app.ensure_sync(fn)(*args, **kwargs)
           ^^^^^^^^^^^^^^^^^^^^^^^^^^^^^^^^^^^^^^^^^^^^
  File "D:\practicum\kostiner-tenders\kostiner-tenders-back\controllers\tender_controller.py", line 47, in get
    abort(500, "message: Internal server error. Please contact support.")
  File "D:\practicum\kostiner-tenders\kostiner-tenders-back\.venv\Lib\site-packages\flask_restx\errors.py", line 28, in abort
    flask.abort(code)
  File "D:\practicum\kostiner-tenders\kostiner-tenders-back\.venv\Lib\site-packages\flask\helpers.py", line 272, in abort
    current_app.aborter(code, *args, **kwargs)
  File "D:\practicum\kostiner-tenders\kostiner-tenders-back\.venv\Lib\site-packages\werkzeug\exceptions.py", line 863, in __call__
    raise self.mapping[code](*args, **kwargs)
werkzeug.exceptions.InternalServerError: 500 Internal Server Error: The server encountered an internal error and was unable to complete your request. Either the server is overloaded or there is an error in the application.
2024-08-04 12:05:03,442 - werkzeug - INFO - 127.0.0.1 - - [04/Aug/2024 12:05:03] "[35m[1mGET /api/get-all-tenders HTTP/1.1[0m" 500 -
2024-08-04 12:10:08,546 - werkzeug - INFO -  * Detected change in 'D:\\practicum\\kostiner-tenders\\kostiner-tenders-back\\services\\tender_service.py', reloading
2024-08-04 12:10:09,187 - werkzeug - INFO -  * Restarting with stat
2024-08-04 12:10:23,479 - werkzeug - WARNING -  * Debugger is active!
2024-08-04 12:10:23,486 - werkzeug - INFO -  * Debugger PIN: 120-157-398
2024-08-04 12:10:27,682 - werkzeug - INFO - 127.0.0.1 - - [04/Aug/2024 12:10:27] "POST /auth/login HTTP/1.1" 200 -
2024-08-04 12:10:43,290 - werkzeug - INFO - 127.0.0.1 - - [04/Aug/2024 12:10:43] "GET /api/get-all-users HTTP/1.1" 200 -
2024-08-04 12:11:01,672 - root - ERROR - Invalid purchase end date format: Provided date string is None
2024-08-04 12:11:01,672 - root - ERROR - tender controller Exception msg: 400 Bad Request: The browser (or proxy) sent a request that this server could not understand.
2024-08-04 12:11:01,672 - app - ERROR - Exception on /api/get-all-tenders [GET]
Traceback (most recent call last):
  File "D:\practicum\kostiner-tenders\kostiner-tenders-back\controllers\tender_controller.py", line 33, in get
    list_array = tender_service.get_all(user, search_date)
                 ^^^^^^^^^^^^^^^^^^^^^^^^^^^^^^^^^^^^^^^^^
  File "D:\practicum\kostiner-tenders\kostiner-tenders-back\services\tender_service.py", line 61, in get_all
    purchase_end_date = parse_date(purchase.get('purchase_end_date  or missing data'),
                        ^^^^^^^^^^^^^^^^^^^^^^^^^^^^^^^^^^^^^^^^^^^^^^^^^^^^^^^^^^^^^^
  File "D:\practicum\kostiner-tenders\kostiner-tenders-back\services\tender_service.py", line 42, in parse_date
    abort(400, 'missing data')
  File "D:\practicum\kostiner-tenders\kostiner-tenders-back\.venv\Lib\site-packages\flask_restx\errors.py", line 28, in abort
    flask.abort(code)
  File "D:\practicum\kostiner-tenders\kostiner-tenders-back\.venv\Lib\site-packages\flask\helpers.py", line 272, in abort
    current_app.aborter(code, *args, **kwargs)
  File "D:\practicum\kostiner-tenders\kostiner-tenders-back\.venv\Lib\site-packages\werkzeug\exceptions.py", line 863, in __call__
    raise self.mapping[code](*args, **kwargs)
werkzeug.exceptions.BadRequest: 400 Bad Request: The browser (or proxy) sent a request that this server could not understand.

During handling of the above exception, another exception occurred:

Traceback (most recent call last):
  File "D:\practicum\kostiner-tenders\kostiner-tenders-back\.venv\Lib\site-packages\flask\app.py", line 880, in full_dispatch_request
    rv = self.dispatch_request()
         ^^^^^^^^^^^^^^^^^^^^^^^
  File "D:\practicum\kostiner-tenders\kostiner-tenders-back\.venv\Lib\site-packages\flask\app.py", line 865, in dispatch_request
    return self.ensure_sync(self.view_functions[rule.endpoint])(**view_args)  # type: ignore[no-any-return]
           ^^^^^^^^^^^^^^^^^^^^^^^^^^^^^^^^^^^^^^^^^^^^^^^^^^^^^^^^^^^^^^^^^
  File "D:\practicum\kostiner-tenders\kostiner-tenders-back\.venv\Lib\site-packages\flask_restx\api.py", line 402, in wrapper
    resp = resource(*args, **kwargs)
           ^^^^^^^^^^^^^^^^^^^^^^^^^
  File "D:\practicum\kostiner-tenders\kostiner-tenders-back\.venv\Lib\site-packages\flask\views.py", line 110, in view
    return current_app.ensure_sync(self.dispatch_request)(**kwargs)  # type: ignore[no-any-return]
           ^^^^^^^^^^^^^^^^^^^^^^^^^^^^^^^^^^^^^^^^^^^^^^^^^^^^^^^^
  File "D:\practicum\kostiner-tenders\kostiner-tenders-back\.venv\Lib\site-packages\flask_restx\resource.py", line 41, in dispatch_request
    resp = meth(*args, **kwargs)
           ^^^^^^^^^^^^^^^^^^^^^
  File "D:\practicum\kostiner-tenders\kostiner-tenders-back\.venv\Lib\site-packages\flask_restx\marshalling.py", line 244, in wrapper
    resp = f(*args, **kwargs)
           ^^^^^^^^^^^^^^^^^^
  File "D:\practicum\kostiner-tenders\kostiner-tenders-back\.venv\Lib\site-packages\flask_jwt_extended\view_decorators.py", line 170, in decorator
    return current_app.ensure_sync(fn)(*args, **kwargs)
           ^^^^^^^^^^^^^^^^^^^^^^^^^^^^^^^^^^^^^^^^^^^^
  File "D:\practicum\kostiner-tenders\kostiner-tenders-back\controllers\tender_controller.py", line 47, in get
    abort(500, "message: Internal server error. Please contact support.")
  File "D:\practicum\kostiner-tenders\kostiner-tenders-back\.venv\Lib\site-packages\flask_restx\errors.py", line 28, in abort
    flask.abort(code)
  File "D:\practicum\kostiner-tenders\kostiner-tenders-back\.venv\Lib\site-packages\flask\helpers.py", line 272, in abort
    current_app.aborter(code, *args, **kwargs)
  File "D:\practicum\kostiner-tenders\kostiner-tenders-back\.venv\Lib\site-packages\werkzeug\exceptions.py", line 863, in __call__
    raise self.mapping[code](*args, **kwargs)
werkzeug.exceptions.InternalServerError: 500 Internal Server Error: The server encountered an internal error and was unable to complete your request. Either the server is overloaded or there is an error in the application.
2024-08-04 12:11:01,672 - app - ERROR - Exception on /api/get-all-tenders [GET]
Traceback (most recent call last):
  File "D:\practicum\kostiner-tenders\kostiner-tenders-back\controllers\tender_controller.py", line 33, in get
    list_array = tender_service.get_all(user, search_date)
                 ^^^^^^^^^^^^^^^^^^^^^^^^^^^^^^^^^^^^^^^^^
  File "D:\practicum\kostiner-tenders\kostiner-tenders-back\services\tender_service.py", line 61, in get_all
    purchase_end_date = parse_date(purchase.get('purchase_end_date  or missing data'),
                        ^^^^^^^^^^^^^^^^^^^^^^^^^^^^^^^^^^^^^^^^^^^^^^^^^^^^^^^^^^^^^^
  File "D:\practicum\kostiner-tenders\kostiner-tenders-back\services\tender_service.py", line 42, in parse_date
    abort(400, 'missing data')
  File "D:\practicum\kostiner-tenders\kostiner-tenders-back\.venv\Lib\site-packages\flask_restx\errors.py", line 28, in abort
    flask.abort(code)
  File "D:\practicum\kostiner-tenders\kostiner-tenders-back\.venv\Lib\site-packages\flask\helpers.py", line 272, in abort
    current_app.aborter(code, *args, **kwargs)
  File "D:\practicum\kostiner-tenders\kostiner-tenders-back\.venv\Lib\site-packages\werkzeug\exceptions.py", line 863, in __call__
    raise self.mapping[code](*args, **kwargs)
werkzeug.exceptions.BadRequest: 400 Bad Request: The browser (or proxy) sent a request that this server could not understand.

During handling of the above exception, another exception occurred:

Traceback (most recent call last):
  File "D:\practicum\kostiner-tenders\kostiner-tenders-back\.venv\Lib\site-packages\flask\app.py", line 880, in full_dispatch_request
    rv = self.dispatch_request()
         ^^^^^^^^^^^^^^^^^^^^^^^
  File "D:\practicum\kostiner-tenders\kostiner-tenders-back\.venv\Lib\site-packages\flask\app.py", line 865, in dispatch_request
    return self.ensure_sync(self.view_functions[rule.endpoint])(**view_args)  # type: ignore[no-any-return]
           ^^^^^^^^^^^^^^^^^^^^^^^^^^^^^^^^^^^^^^^^^^^^^^^^^^^^^^^^^^^^^^^^^
  File "D:\practicum\kostiner-tenders\kostiner-tenders-back\.venv\Lib\site-packages\flask_restx\api.py", line 402, in wrapper
    resp = resource(*args, **kwargs)
           ^^^^^^^^^^^^^^^^^^^^^^^^^
  File "D:\practicum\kostiner-tenders\kostiner-tenders-back\.venv\Lib\site-packages\flask\views.py", line 110, in view
    return current_app.ensure_sync(self.dispatch_request)(**kwargs)  # type: ignore[no-any-return]
           ^^^^^^^^^^^^^^^^^^^^^^^^^^^^^^^^^^^^^^^^^^^^^^^^^^^^^^^^
  File "D:\practicum\kostiner-tenders\kostiner-tenders-back\.venv\Lib\site-packages\flask_restx\resource.py", line 41, in dispatch_request
    resp = meth(*args, **kwargs)
           ^^^^^^^^^^^^^^^^^^^^^
  File "D:\practicum\kostiner-tenders\kostiner-tenders-back\.venv\Lib\site-packages\flask_restx\marshalling.py", line 244, in wrapper
    resp = f(*args, **kwargs)
           ^^^^^^^^^^^^^^^^^^
  File "D:\practicum\kostiner-tenders\kostiner-tenders-back\.venv\Lib\site-packages\flask_jwt_extended\view_decorators.py", line 170, in decorator
    return current_app.ensure_sync(fn)(*args, **kwargs)
           ^^^^^^^^^^^^^^^^^^^^^^^^^^^^^^^^^^^^^^^^^^^^
  File "D:\practicum\kostiner-tenders\kostiner-tenders-back\controllers\tender_controller.py", line 47, in get
    abort(500, "message: Internal server error. Please contact support.")
  File "D:\practicum\kostiner-tenders\kostiner-tenders-back\.venv\Lib\site-packages\flask_restx\errors.py", line 28, in abort
    flask.abort(code)
  File "D:\practicum\kostiner-tenders\kostiner-tenders-back\.venv\Lib\site-packages\flask\helpers.py", line 272, in abort
    current_app.aborter(code, *args, **kwargs)
  File "D:\practicum\kostiner-tenders\kostiner-tenders-back\.venv\Lib\site-packages\werkzeug\exceptions.py", line 863, in __call__
    raise self.mapping[code](*args, **kwargs)
werkzeug.exceptions.InternalServerError: 500 Internal Server Error: The server encountered an internal error and was unable to complete your request. Either the server is overloaded or there is an error in the application.
2024-08-04 12:11:01,715 - werkzeug - INFO - 127.0.0.1 - - [04/Aug/2024 12:11:01] "[35m[1mGET /api/get-all-tenders HTTP/1.1[0m" 500 -
2024-08-04 12:12:49,289 - werkzeug - INFO -  * Detected change in 'D:\\practicum\\kostiner-tenders\\kostiner-tenders-back\\services\\tender_service.py', reloading
2024-08-04 12:12:49,931 - werkzeug - INFO -  * Restarting with stat
2024-08-04 12:13:03,846 - werkzeug - WARNING -  * Debugger is active!
2024-08-04 12:13:03,853 - werkzeug - INFO -  * Debugger PIN: 120-157-398
2024-08-04 12:13:23,842 - root - ERROR - Invalid purchase end date format: Provided date string is None
2024-08-04 12:13:23,842 - root - ERROR - tender controller Exception msg: 400 Bad Request: The browser (or proxy) sent a request that this server could not understand.
2024-08-04 12:13:23,843 - app - ERROR - Exception on /api/get-all-tenders [GET]
Traceback (most recent call last):
  File "D:\practicum\kostiner-tenders\kostiner-tenders-back\controllers\tender_controller.py", line 33, in get
    list_array = tender_service.get_all(user, search_date)
                 ^^^^^^^^^^^^^^^^^^^^^^^^^^^^^^^^^^^^^^^^^
  File "D:\practicum\kostiner-tenders\kostiner-tenders-back\services\tender_service.py", line 62, in get_all
    purchase_end_date = parse_date(purchase.get('purchase_end_date  or missing data'),
                        ^^^^^^^^^^^^^^^^^^^^^^^^^^^^^^^^^^^^^^^^^^^^^^^^^^^^^^^^^^^^^^
  File "D:\practicum\kostiner-tenders\kostiner-tenders-back\services\tender_service.py", line 42, in parse_date
    abort(400, 'missing data')
  File "D:\practicum\kostiner-tenders\kostiner-tenders-back\.venv\Lib\site-packages\flask_restx\errors.py", line 28, in abort
    flask.abort(code)
  File "D:\practicum\kostiner-tenders\kostiner-tenders-back\.venv\Lib\site-packages\flask\helpers.py", line 272, in abort
    current_app.aborter(code, *args, **kwargs)
  File "D:\practicum\kostiner-tenders\kostiner-tenders-back\.venv\Lib\site-packages\werkzeug\exceptions.py", line 863, in __call__
    raise self.mapping[code](*args, **kwargs)
werkzeug.exceptions.BadRequest: 400 Bad Request: The browser (or proxy) sent a request that this server could not understand.

During handling of the above exception, another exception occurred:

Traceback (most recent call last):
  File "D:\practicum\kostiner-tenders\kostiner-tenders-back\.venv\Lib\site-packages\flask\app.py", line 880, in full_dispatch_request
    rv = self.dispatch_request()
         ^^^^^^^^^^^^^^^^^^^^^^^
  File "D:\practicum\kostiner-tenders\kostiner-tenders-back\.venv\Lib\site-packages\flask\app.py", line 865, in dispatch_request
    return self.ensure_sync(self.view_functions[rule.endpoint])(**view_args)  # type: ignore[no-any-return]
           ^^^^^^^^^^^^^^^^^^^^^^^^^^^^^^^^^^^^^^^^^^^^^^^^^^^^^^^^^^^^^^^^^
  File "D:\practicum\kostiner-tenders\kostiner-tenders-back\.venv\Lib\site-packages\flask_restx\api.py", line 402, in wrapper
    resp = resource(*args, **kwargs)
           ^^^^^^^^^^^^^^^^^^^^^^^^^
  File "D:\practicum\kostiner-tenders\kostiner-tenders-back\.venv\Lib\site-packages\flask\views.py", line 110, in view
    return current_app.ensure_sync(self.dispatch_request)(**kwargs)  # type: ignore[no-any-return]
           ^^^^^^^^^^^^^^^^^^^^^^^^^^^^^^^^^^^^^^^^^^^^^^^^^^^^^^^^
  File "D:\practicum\kostiner-tenders\kostiner-tenders-back\.venv\Lib\site-packages\flask_restx\resource.py", line 41, in dispatch_request
    resp = meth(*args, **kwargs)
           ^^^^^^^^^^^^^^^^^^^^^
  File "D:\practicum\kostiner-tenders\kostiner-tenders-back\.venv\Lib\site-packages\flask_restx\marshalling.py", line 244, in wrapper
    resp = f(*args, **kwargs)
           ^^^^^^^^^^^^^^^^^^
  File "D:\practicum\kostiner-tenders\kostiner-tenders-back\.venv\Lib\site-packages\flask_jwt_extended\view_decorators.py", line 170, in decorator
    return current_app.ensure_sync(fn)(*args, **kwargs)
           ^^^^^^^^^^^^^^^^^^^^^^^^^^^^^^^^^^^^^^^^^^^^
  File "D:\practicum\kostiner-tenders\kostiner-tenders-back\controllers\tender_controller.py", line 47, in get
    abort(500, "message: Internal server error. Please contact support.")
  File "D:\practicum\kostiner-tenders\kostiner-tenders-back\.venv\Lib\site-packages\flask_restx\errors.py", line 28, in abort
    flask.abort(code)
  File "D:\practicum\kostiner-tenders\kostiner-tenders-back\.venv\Lib\site-packages\flask\helpers.py", line 272, in abort
    current_app.aborter(code, *args, **kwargs)
  File "D:\practicum\kostiner-tenders\kostiner-tenders-back\.venv\Lib\site-packages\werkzeug\exceptions.py", line 863, in __call__
    raise self.mapping[code](*args, **kwargs)
werkzeug.exceptions.InternalServerError: 500 Internal Server Error: The server encountered an internal error and was unable to complete your request. Either the server is overloaded or there is an error in the application.
2024-08-04 12:13:23,843 - app - ERROR - Exception on /api/get-all-tenders [GET]
Traceback (most recent call last):
  File "D:\practicum\kostiner-tenders\kostiner-tenders-back\controllers\tender_controller.py", line 33, in get
    list_array = tender_service.get_all(user, search_date)
                 ^^^^^^^^^^^^^^^^^^^^^^^^^^^^^^^^^^^^^^^^^
  File "D:\practicum\kostiner-tenders\kostiner-tenders-back\services\tender_service.py", line 62, in get_all
    purchase_end_date = parse_date(purchase.get('purchase_end_date  or missing data'),
                        ^^^^^^^^^^^^^^^^^^^^^^^^^^^^^^^^^^^^^^^^^^^^^^^^^^^^^^^^^^^^^^
  File "D:\practicum\kostiner-tenders\kostiner-tenders-back\services\tender_service.py", line 42, in parse_date
    abort(400, 'missing data')
  File "D:\practicum\kostiner-tenders\kostiner-tenders-back\.venv\Lib\site-packages\flask_restx\errors.py", line 28, in abort
    flask.abort(code)
  File "D:\practicum\kostiner-tenders\kostiner-tenders-back\.venv\Lib\site-packages\flask\helpers.py", line 272, in abort
    current_app.aborter(code, *args, **kwargs)
  File "D:\practicum\kostiner-tenders\kostiner-tenders-back\.venv\Lib\site-packages\werkzeug\exceptions.py", line 863, in __call__
    raise self.mapping[code](*args, **kwargs)
werkzeug.exceptions.BadRequest: 400 Bad Request: The browser (or proxy) sent a request that this server could not understand.

During handling of the above exception, another exception occurred:

Traceback (most recent call last):
  File "D:\practicum\kostiner-tenders\kostiner-tenders-back\.venv\Lib\site-packages\flask\app.py", line 880, in full_dispatch_request
    rv = self.dispatch_request()
         ^^^^^^^^^^^^^^^^^^^^^^^
  File "D:\practicum\kostiner-tenders\kostiner-tenders-back\.venv\Lib\site-packages\flask\app.py", line 865, in dispatch_request
    return self.ensure_sync(self.view_functions[rule.endpoint])(**view_args)  # type: ignore[no-any-return]
           ^^^^^^^^^^^^^^^^^^^^^^^^^^^^^^^^^^^^^^^^^^^^^^^^^^^^^^^^^^^^^^^^^
  File "D:\practicum\kostiner-tenders\kostiner-tenders-back\.venv\Lib\site-packages\flask_restx\api.py", line 402, in wrapper
    resp = resource(*args, **kwargs)
           ^^^^^^^^^^^^^^^^^^^^^^^^^
  File "D:\practicum\kostiner-tenders\kostiner-tenders-back\.venv\Lib\site-packages\flask\views.py", line 110, in view
    return current_app.ensure_sync(self.dispatch_request)(**kwargs)  # type: ignore[no-any-return]
           ^^^^^^^^^^^^^^^^^^^^^^^^^^^^^^^^^^^^^^^^^^^^^^^^^^^^^^^^
  File "D:\practicum\kostiner-tenders\kostiner-tenders-back\.venv\Lib\site-packages\flask_restx\resource.py", line 41, in dispatch_request
    resp = meth(*args, **kwargs)
           ^^^^^^^^^^^^^^^^^^^^^
  File "D:\practicum\kostiner-tenders\kostiner-tenders-back\.venv\Lib\site-packages\flask_restx\marshalling.py", line 244, in wrapper
    resp = f(*args, **kwargs)
           ^^^^^^^^^^^^^^^^^^
  File "D:\practicum\kostiner-tenders\kostiner-tenders-back\.venv\Lib\site-packages\flask_jwt_extended\view_decorators.py", line 170, in decorator
    return current_app.ensure_sync(fn)(*args, **kwargs)
           ^^^^^^^^^^^^^^^^^^^^^^^^^^^^^^^^^^^^^^^^^^^^
  File "D:\practicum\kostiner-tenders\kostiner-tenders-back\controllers\tender_controller.py", line 47, in get
    abort(500, "message: Internal server error. Please contact support.")
  File "D:\practicum\kostiner-tenders\kostiner-tenders-back\.venv\Lib\site-packages\flask_restx\errors.py", line 28, in abort
    flask.abort(code)
  File "D:\practicum\kostiner-tenders\kostiner-tenders-back\.venv\Lib\site-packages\flask\helpers.py", line 272, in abort
    current_app.aborter(code, *args, **kwargs)
  File "D:\practicum\kostiner-tenders\kostiner-tenders-back\.venv\Lib\site-packages\werkzeug\exceptions.py", line 863, in __call__
    raise self.mapping[code](*args, **kwargs)
werkzeug.exceptions.InternalServerError: 500 Internal Server Error: The server encountered an internal error and was unable to complete your request. Either the server is overloaded or there is an error in the application.
2024-08-04 12:13:23,874 - werkzeug - INFO - 127.0.0.1 - - [04/Aug/2024 12:13:23] "[35m[1mGET /api/get-all-tenders HTTP/1.1[0m" 500 -
2024-08-04 14:50:16,987 - werkzeug - INFO - [31m[1mWARNING: This is a development server. Do not use it in a production deployment. Use a production WSGI server instead.[0m
 * Running on http://127.0.0.1:5000
2024-08-04 14:50:16,988 - werkzeug - INFO - [33mPress CTRL+C to quit[0m
2024-08-04 14:50:16,992 - werkzeug - INFO -  * Restarting with stat
2024-08-04 14:50:31,491 - werkzeug - WARNING -  * Debugger is active!
2024-08-04 14:50:31,522 - werkzeug - INFO -  * Debugger PIN: 120-157-398
2024-08-04 14:50:31,870 - werkzeug - INFO - 127.0.0.1 - - [04/Aug/2024 14:50:31] "[31m[1mGET /api/get-all-tenders HTTP/1.1[0m" 401 -
2024-08-04 14:50:37,848 - werkzeug - INFO - 127.0.0.1 - - [04/Aug/2024 14:50:37] "POST /auth/login HTTP/1.1" 200 -
2024-08-04 14:50:55,697 - root - ERROR - tender controller Exception msg: 400 Bad Request: The browser (or proxy) sent a request that this server could not understand.
2024-08-04 14:50:55,698 - app - ERROR - Exception on /api/get-all-tenders [GET]
Traceback (most recent call last):
  File "D:\practicum\kostiner-tenders\kostiner-tenders-back\controllers\tender_controller.py", line 33, in get
    list_array = tender_service.get_all(user, search_date)
                 ^^^^^^^^^^^^^^^^^^^^^^^^^^^^^^^^^^^^^^^^^
  File "D:\practicum\kostiner-tenders\kostiner-tenders-back\services\tender_service.py", line 31, in get_all
    abort(400, 'user invalid')
  File "D:\practicum\kostiner-tenders\kostiner-tenders-back\.venv\Lib\site-packages\flask_restx\errors.py", line 29, in abort
    flask.abort(code)
  File "D:\practicum\kostiner-tenders\kostiner-tenders-back\.venv\Lib\site-packages\flask\helpers.py", line 272, in abort
    current_app.aborter(code, *args, **kwargs)
  File "D:\practicum\kostiner-tenders\kostiner-tenders-back\.venv\Lib\site-packages\werkzeug\exceptions.py", line 863, in __call__
    raise self.mapping[code](*args, **kwargs)
werkzeug.exceptions.BadRequest: 400 Bad Request: The browser (or proxy) sent a request that this server could not understand.

During handling of the above exception, another exception occurred:

Traceback (most recent call last):
  File "D:\practicum\kostiner-tenders\kostiner-tenders-back\.venv\Lib\site-packages\flask\app.py", line 880, in full_dispatch_request
    rv = self.dispatch_request()
         ^^^^^^^^^^^^^^^^^^^^^^^
  File "D:\practicum\kostiner-tenders\kostiner-tenders-back\.venv\Lib\site-packages\flask\app.py", line 865, in dispatch_request
    return self.ensure_sync(self.view_functions[rule.endpoint])(**view_args)  # type: ignore[no-any-return]
           ^^^^^^^^^^^^^^^^^^^^^^^^^^^^^^^^^^^^^^^^^^^^^^^^^^^^^^^^^^^^^^^^^
  File "D:\practicum\kostiner-tenders\kostiner-tenders-back\.venv\Lib\site-packages\flask_restx\api.py", line 402, in wrapper
    resp = resource(*args, **kwargs)
           ^^^^^^^^^^^^^^^^^^^^^^^^^
  File "D:\practicum\kostiner-tenders\kostiner-tenders-back\.venv\Lib\site-packages\flask\views.py", line 110, in view
    return current_app.ensure_sync(self.dispatch_request)(**kwargs)  # type: ignore[no-any-return]
           ^^^^^^^^^^^^^^^^^^^^^^^^^^^^^^^^^^^^^^^^^^^^^^^^^^^^^^^^
  File "D:\practicum\kostiner-tenders\kostiner-tenders-back\.venv\Lib\site-packages\flask_restx\resource.py", line 41, in dispatch_request
    resp = meth(*args, **kwargs)
           ^^^^^^^^^^^^^^^^^^^^^
  File "D:\practicum\kostiner-tenders\kostiner-tenders-back\.venv\Lib\site-packages\flask_restx\marshalling.py", line 244, in wrapper
    resp = f(*args, **kwargs)
           ^^^^^^^^^^^^^^^^^^
  File "D:\practicum\kostiner-tenders\kostiner-tenders-back\.venv\Lib\site-packages\flask_jwt_extended\view_decorators.py", line 170, in decorator
    return current_app.ensure_sync(fn)(*args, **kwargs)
           ^^^^^^^^^^^^^^^^^^^^^^^^^^^^^^^^^^^^^^^^^^^^
  File "D:\practicum\kostiner-tenders\kostiner-tenders-back\controllers\tender_controller.py", line 47, in get
    abort(500, "message: Internal server error. Please contact support.")
  File "D:\practicum\kostiner-tenders\kostiner-tenders-back\.venv\Lib\site-packages\flask_restx\errors.py", line 29, in abort
    flask.abort(code)
  File "D:\practicum\kostiner-tenders\kostiner-tenders-back\.venv\Lib\site-packages\flask\helpers.py", line 272, in abort
    current_app.aborter(code, *args, **kwargs)
  File "D:\practicum\kostiner-tenders\kostiner-tenders-back\.venv\Lib\site-packages\werkzeug\exceptions.py", line 863, in __call__
    raise self.mapping[code](*args, **kwargs)
werkzeug.exceptions.InternalServerError: 500 Internal Server Error: The server encountered an internal error and was unable to complete your request. Either the server is overloaded or there is an error in the application.
2024-08-04 14:50:55,698 - app - ERROR - Exception on /api/get-all-tenders [GET]
Traceback (most recent call last):
  File "D:\practicum\kostiner-tenders\kostiner-tenders-back\controllers\tender_controller.py", line 33, in get
    list_array = tender_service.get_all(user, search_date)
                 ^^^^^^^^^^^^^^^^^^^^^^^^^^^^^^^^^^^^^^^^^
  File "D:\practicum\kostiner-tenders\kostiner-tenders-back\services\tender_service.py", line 31, in get_all
    abort(400, 'user invalid')
  File "D:\practicum\kostiner-tenders\kostiner-tenders-back\.venv\Lib\site-packages\flask_restx\errors.py", line 29, in abort
    flask.abort(code)
  File "D:\practicum\kostiner-tenders\kostiner-tenders-back\.venv\Lib\site-packages\flask\helpers.py", line 272, in abort
    current_app.aborter(code, *args, **kwargs)
  File "D:\practicum\kostiner-tenders\kostiner-tenders-back\.venv\Lib\site-packages\werkzeug\exceptions.py", line 863, in __call__
    raise self.mapping[code](*args, **kwargs)
werkzeug.exceptions.BadRequest: 400 Bad Request: The browser (or proxy) sent a request that this server could not understand.

During handling of the above exception, another exception occurred:

Traceback (most recent call last):
  File "D:\practicum\kostiner-tenders\kostiner-tenders-back\.venv\Lib\site-packages\flask\app.py", line 880, in full_dispatch_request
    rv = self.dispatch_request()
         ^^^^^^^^^^^^^^^^^^^^^^^
  File "D:\practicum\kostiner-tenders\kostiner-tenders-back\.venv\Lib\site-packages\flask\app.py", line 865, in dispatch_request
    return self.ensure_sync(self.view_functions[rule.endpoint])(**view_args)  # type: ignore[no-any-return]
           ^^^^^^^^^^^^^^^^^^^^^^^^^^^^^^^^^^^^^^^^^^^^^^^^^^^^^^^^^^^^^^^^^
  File "D:\practicum\kostiner-tenders\kostiner-tenders-back\.venv\Lib\site-packages\flask_restx\api.py", line 402, in wrapper
    resp = resource(*args, **kwargs)
           ^^^^^^^^^^^^^^^^^^^^^^^^^
  File "D:\practicum\kostiner-tenders\kostiner-tenders-back\.venv\Lib\site-packages\flask\views.py", line 110, in view
    return current_app.ensure_sync(self.dispatch_request)(**kwargs)  # type: ignore[no-any-return]
           ^^^^^^^^^^^^^^^^^^^^^^^^^^^^^^^^^^^^^^^^^^^^^^^^^^^^^^^^
  File "D:\practicum\kostiner-tenders\kostiner-tenders-back\.venv\Lib\site-packages\flask_restx\resource.py", line 41, in dispatch_request
    resp = meth(*args, **kwargs)
           ^^^^^^^^^^^^^^^^^^^^^
  File "D:\practicum\kostiner-tenders\kostiner-tenders-back\.venv\Lib\site-packages\flask_restx\marshalling.py", line 244, in wrapper
    resp = f(*args, **kwargs)
           ^^^^^^^^^^^^^^^^^^
  File "D:\practicum\kostiner-tenders\kostiner-tenders-back\.venv\Lib\site-packages\flask_jwt_extended\view_decorators.py", line 170, in decorator
    return current_app.ensure_sync(fn)(*args, **kwargs)
           ^^^^^^^^^^^^^^^^^^^^^^^^^^^^^^^^^^^^^^^^^^^^
  File "D:\practicum\kostiner-tenders\kostiner-tenders-back\controllers\tender_controller.py", line 47, in get
    abort(500, "message: Internal server error. Please contact support.")
  File "D:\practicum\kostiner-tenders\kostiner-tenders-back\.venv\Lib\site-packages\flask_restx\errors.py", line 29, in abort
    flask.abort(code)
  File "D:\practicum\kostiner-tenders\kostiner-tenders-back\.venv\Lib\site-packages\flask\helpers.py", line 272, in abort
    current_app.aborter(code, *args, **kwargs)
  File "D:\practicum\kostiner-tenders\kostiner-tenders-back\.venv\Lib\site-packages\werkzeug\exceptions.py", line 863, in __call__
    raise self.mapping[code](*args, **kwargs)
werkzeug.exceptions.InternalServerError: 500 Internal Server Error: The server encountered an internal error and was unable to complete your request. Either the server is overloaded or there is an error in the application.
2024-08-04 14:50:55,744 - werkzeug - INFO - 127.0.0.1 - - [04/Aug/2024 14:50:55] "[35m[1mGET /api/get-all-tenders HTTP/1.1[0m" 500 -
2024-08-04 14:51:53,672 - werkzeug - INFO -  * Detected change in 'D:\\practicum\\kostiner-tenders\\kostiner-tenders-back\\services\\tender_service.py', reloading
2024-08-04 14:51:54,227 - werkzeug - INFO -  * Restarting with stat
2024-08-04 14:52:09,371 - werkzeug - WARNING -  * Debugger is active!
2024-08-04 14:52:09,392 - werkzeug - INFO -  * Debugger PIN: 120-157-398
2024-08-04 14:52:16,836 - werkzeug - INFO -  * Detected change in 'D:\\practicum\\kostiner-tenders\\kostiner-tenders-back\\services\\tender_service.py', reloading
2024-08-04 14:52:17,497 - werkzeug - INFO -  * Restarting with stat
2024-08-04 14:52:31,291 - werkzeug - WARNING -  * Debugger is active!
2024-08-04 14:52:31,298 - werkzeug - INFO -  * Debugger PIN: 120-157-398
2024-08-04 14:52:47,345 - werkzeug - INFO -  * Detected change in 'D:\\practicum\\kostiner-tenders\\kostiner-tenders-back\\services\\tender_service.py', reloading
2024-08-04 14:52:47,965 - werkzeug - INFO -  * Restarting with stat
2024-08-04 14:53:01,581 - werkzeug - WARNING -  * Debugger is active!
2024-08-04 14:53:01,589 - werkzeug - INFO -  * Debugger PIN: 120-157-398
2024-08-04 15:27:03,084 - werkzeug - INFO -  * Detected change in 'D:\\practicum\\kostiner-tenders\\kostiner-tenders-back\\services\\tender_service.py', reloading
2024-08-04 15:27:03,704 - werkzeug - INFO -  * Restarting with stat
2024-08-04 15:27:19,863 - werkzeug - WARNING -  * Debugger is active!
2024-08-04 15:27:19,893 - werkzeug - INFO -  * Debugger PIN: 120-157-398
2024-08-04 17:49:29,278 - werkzeug - INFO -  * Detected change in 'D:\\practicum\\kostiner-tenders\\kostiner-tenders-back\\services\\tender_service.py', reloading
2024-08-04 17:49:29,900 - werkzeug - INFO -  * Restarting with stat
2024-08-04 17:49:44,955 - werkzeug - WARNING -  * Debugger is active!
2024-08-04 17:49:44,962 - werkzeug - INFO -  * Debugger PIN: 120-157-398
2024-08-04 23:05:25,352 - werkzeug - INFO -  * Detected change in 'D:\\practicum\\kostiner-tenders\\kostiner-tenders-back\\dal\\user_repo.py', reloading
2024-08-04 23:05:26,164 - werkzeug - INFO -  * Restarting with stat
2024-08-04 23:07:09,395 - werkzeug - INFO -  * Restarting with stat
2024-08-04 23:25:33,172 - werkzeug - INFO -  * Restarting with stat
2024-08-04 23:27:33,892 - werkzeug - INFO -  * Restarting with stat
2024-08-04 23:29:05,736 - werkzeug - INFO -  * Restarting with stat
2024-08-04 23:29:29,026 - werkzeug - INFO -  * Restarting with stat
2024-08-04 23:38:28,706 - werkzeug - INFO -  * Restarting with stat
2024-08-04 23:38:56,162 - werkzeug - INFO -  * Restarting with stat
2024-08-04 23:41:25,068 - werkzeug - INFO -  * Restarting with stat
2024-08-04 23:42:32,389 - werkzeug - INFO -  * Restarting with stat
